Workbook

Sheet Original Data
A1: Order ID | B1: Order Date | C1: Customer Name | D1: Product | E1: Category | F1: Region | G1: Quantity | H1: Unit Price | I1: Revenue
A2: ORD0033 | B2: 46173 | C2: Meena Joshi | D2: Laptop | E2: Electronics | F2: North | G2: 5 | H2: 55593.14 | I2: 277965.7
A3: ORD0092 | B3: 46240 | C3: Sneha Patel | D3: Laptop | E3: Electronics | F3: West | G3: 5 | H3: 52241.18 | I3: 261205.9
A4: ORD0071 | B4: 46232 | C4: Manoj Reddy | D4: Laptop | E4: Electronics | F4: East | G4: 4 | H4: 51946.77 | I4: 207787.08
A5: ORD0065 | B5: 46060 | C5: Divya Menon | D5: Laptop | E5: Electronics | F5: South | G5: 3 | H5: 55907.61 | I5: 167722.83
A6: ORD0066 | B6: 46261 | C6: Priya Reddy | D6: Laptop | E6: Electronics | F6: East | G6: 3 | H6: 53511.17 | I6: 160533.51
A7: ORD0111 | B7: 46040 | C7: Priya Reddy | D7: Laptop | E7: Electronics | F7: North | G7: 3 | H7: 51966.44 | I7: 155899.32
A8: ORD0048 | B8: 46172 | C8: Kavya Rao | D8: Laptop | E8: Electronics | F8: Central | G8: 3 | H8: 50128.82 | I8: 150386.46
A9: ORD0051 | B9: 46175 | C9: Priya Reddy | D9: Smartphone | E9: Electronics | F9: Central | G9: 5 | H9: 26578.81 | I9: 132894.05
A10: ORD0035 | B10: 46194 | C10: Kavya Rao | D10: Smartphone | E10: Electronics | F10: South | G10: 5 | H10: 26532.83 | I10: 132664.15
A11: ORD0002 | B11: 46131 | C11: Priya Reddy | D11: Smartphone | E11: Electronics | F11: North | G11: 5 | H11: 25686.86 | I11: 128434.3
A12: ORD0050 | B12: 46243 | C12: Meena Joshi | D12: Smartphone | E12: Electronics | F12: West | G12: 5 | H12: 25580.58 | I12: 127902.9
A13: ORD0028 | B13: 46217 | C13: Swathi Das | D13: Smartphone | E13: Electronics | F13: South | G13: 4 | H13: 29769.73 | I13: 119078.92
... A121: ORD0014 | B121: 46031 | C121: Suresh Nair | D121: Mouse | E121: Accessories | F121: West | G121: 1 | H121: 851.23 | I121: 851.23

Sheet Uncleaned Data
A1: Order ID | B1: Order Date | C1: Customer Name | D1: Product | E1: Category | F1: Region | G1: Quantity | H1: Unit Price | I1: Revenue
A2: ORD0001 | B2: 46173 | C2: Meena Joshi | D2: Smartphone | E2: Electronics | F2: South | G2: 1 | H2: 29352.68 | I2: 29352.68
A3: ORD0002 | B3: 46240 | C3: Priya Reddy | D3: Smartphone | E3: Electronics | F3: North | G3: 5 | H3: 25686.86 | I3: 128434.3
A4: ORD0003 | B4: 46232 | C4: Rahul Sharma | D4: SMARTPHONE | E4: Electronics | F4: Central | G4: 2 | H4: 26502.9 | I4: 53005.8
A5: ORD0004 | B5: 46060 | C5: Nikhil Jain | D5: Monitor | E5: Electronics | F5: East | G5: 5 | H5: 14758.56 | I5: 73792.8
A6: ORD0005 | B6: 46261 | C6: Rohit Verma | E6: Electronics | F6: South | G6: 2 | H6: 57179.53 | I6: 114359.06
A7: ORD0006 | B7: 46040 | C7: Sneha Patel | D7: Monitor | E7: Electronics | F7: East | G7: 3 | H7: 13806.63 | I7: 41419.89
A8: ORD0007 | B8: 46172 | C8: Manoj Reddy | D8: Mouse | E8: Accessories | F8: Central | G8: 5 | H8: 857.61 | I8: 4288.05
A9: ORD0008 | B9: 46175 | C9: Lakshmi Devi | D9: Smartphone | E9: Electronics | F9: East | G9: 4 | H9: 25641.28 | I9: 102565.12
A10: ORD0009 | B10: 46194 | C10: Meena Joshi | D10: Printer | E10: Electronics | F10: East | G10: 2 | H10: 12490.97 | I10: 24981.94
A11: ORD0010 | B11: 46131 | C11: Rohit Verma | D11: Smartphone | E11: Electronics | F11: West | G11: 2 | H11: 30052.31 | I11: 60104.62
A12: ORD0011 | B12: 46243 | C12: Rohit Verma | D12: Mouse | F12: North | G12: 2 | H12: 876.63 | I12: 1753.26
A13: ORD0012 | B13: 46217 | C13: Ananya Rao | D13: Printer | E13: Electronics | F13: West | G13: 2 | H13: 12081.94 | I13: 24163.88
A14: ORD0013 | B14: 46167 | C14: Swathi Das | D14: Office Chair | E14: Furniture | F14: South | G14: 3 | H14: 9332.19 | I14: 27996.57
A15: ORD0014 | B15: 46110 | C15: Suresh Nair | D15: Mouse | E15: Accessories | F15: West | G15: 1 | H15: 851.23 | I15: 851.23
A16: ORD0015 | B16: 46122 | C16: Nikhil Jain | D16: Keyboard | E16: Accessories | F16: East | G16: 1 | H16: 1695.95 | I16: 1695.95
A17: ORD0016 | B17: 46098 | D17: Monitor | E17: Electronics | F17: South | G17: 4 | H17: 14686.9 | I17: 58747.6
A18: ORD0017 | B18: 46131 | C18: Swathi Das | D18: Keyboard | E18: Accessories | F18: East | G18: 2 | H18: 1708.79 | I18: 3417.58
A19: ORD0018 | B19: 46137 | C19: Pooja Iyer | D19: Printer | E19: Electronics | F19: South | G19: 4 | H19: 12954.77 | I19: 51819.08
A20: ORD0019 | B20: 46251 | C20: Priya Reddy | D20: HEADPHONES | E20: Electronics | F20: North | G20: 5 | H20: 2496.76 | I20: 12483.8
A21: ORD0020 | B21: 46120 | C21: Lakshmi Devi | D21: Headphones | E21: Electronics | F21: North | G21: 2 | H21: 2646.04 | I21: 5292.08
A22: ORD0021 | B22: 46044 | C22: Ravi Kumar | D22: Office Chair | E22: Furniture | F22: East | G22: -3 | H22: 8663.01 | I22: 34652.04
A23: ORD0022 | B23: 46120 | C23: Swathi Das | D23: Backpack | E23: Accessories | F23: East | G23: 1 | H23: 2279.32 | I23: 2279.32
A24: ORD0023 | B24: 46089 | C24: Manoj Reddy | D24: Mouse | E24: Accessories | F24: North | G24: 1 | H24: 862.83 | I24: 862.83
A25: ORD0024 | B25: 46257 | C25: Sneha Patel | D25: Keyboard | E25: Accessories | F25: East | G25: 5 | H25: 1894.31 | I25: 9471.55
A26: ORD0025 | B26: 46220 | C26: Ananya Rao | D26: Backpack | E26: Accessories | F26: Central | G26: 5 | H26: 2067.52 | I26: 10337.6
A27: ORD0026 | B27: 46080 | C27: Rahul Sharma | D27: Backpack | E27: Accessories | F27: North | H27: 2243.54 | I27: 2243.54
A28: ORD0027 | B28: 46134 | C28: Nikhil Jain | D28: Mouse | E28: Accessories | F28: North | G28: 3 | H28: 853.1 | I28: 2559.3
A29: ORD0028 | B29: 46232 | C29: Swathi Das | D29: Smartphone | E29: Electronics | F29: South | G29: 4 | H29: 29769.73 | I29: 119078.92
A30: ORD0029 | B30: 46250 | C30: Rohit Verma | D30: Headphones | E30: electronics | F30: Central | G30: 4 | H30: 2723.42 | I30: 10893.68
A31: ORD0030 | B31: 46177 | C31: Swathi Das | D31: Printer | E31: Electronics | F31: South | G31: 4 | H31: 13114.47 | I31: 52457.88
A32: ORD0031 | B32: 46260 | C32: Pooja Iyer | D32: Keyboard | E32: Accessories | F32: West | G32: 4 | H32: 1978.25 | I32: 7913
A33: ORD0032 | B33: 46144 | C33: Arjun Kumar | D33: Backpack | E33: Accessories | F33: East | G33: 4 | H33: 2033.24 | I33: 8132.96
A34: ORD0033 | B34: 46125 | C34: Meena Joshi | D34: Laptop | E34: Electronics | F34: North | G34: 5 | H34: 55593.14 | I34: 277965.7
A35: ORD0034 | B35: 46170 | C35: Priya Reddy | D35: Smartphone | E35: Electronics | F35: East | G35: 1 | H35: 26482.07 | I35: 26482.07
A36: ORD0035 | B36: 46264 | C36: Kavya Rao | D36: Smartphone | E36: Electronics | F36: South | G36: 5 | H36: 26532.83 | I36: 132664.15
A37: ORD0036 | B37: 46077 | C37: Nikhil Jain | D37: Backpack | E37: Accessories | F37: Central | G37: 2 | H37: 2298.28 | I37: 4596.56
A38: ORD0037 | B38: 46052 | C38: Divya Menon | D38: Desk | E38: Furniture | F38: South | G38: 2 | H38: 12683.09 | I38: 25366.18
A39: ORD0038 | B39: 46190 | C39: Divya Menon | E39: Electronics | F39: West | G39: 1 | H39: 28890.3 | I39: 28890.3
A40: ORD0039 | B40: 46205 | C40: Sneha Patel | D40: Desk | E40: Furniture | F40: North | G40: 1 | H40: 12416.07 | I40: 12416.07
...

Sheet  Actions Rquired
A1: Issue | B1: Column | C1: Formula/Method | D1: Action
A2: Blank values | B2: Product | C2: COUNTBLANK | D2: Fill/Remove
A3: Blank values | B3: Category | C3: COUNTBLANK | D3: Fill
A4: Duplicate records | B4: All columns | C4: Conditional formating(To Highlet Duplicates)/Remove Duplicates | D4: Remove
A5: Extra spaces | B5: Product | C5: TRIM | D5: Clean
A6: Extra spaces | B6: Category | C6: TRIM | D6: Clean
A7: Incorrect capitalization | B7: Product | C7: PROPER | D7: Standardize
A8: Incorrect capitalization | B8: Category | C8: PROPER | D8: Standardize
A9: Invalid quantity | B9: Quantity | C9: COUNTIF | D9: Correct
A10: Missing category | B10: Category | C10: COUNTBLANK | D10: Fill
A11: Outliers | B11: Quantity | C11: MAX/MIN | D11: Investigate
A12: Missing Customer Name | B12: Customer Name | C12: COUNTBLANK | D12: Fill/Unknown
A13: Missing Revenue | B13: Revenue | C13: COUNTBLANK | D13: Recalculate

Sheet Data Cleaning
A1: Order ID | B1: Order Date | C1: Customer Name | D1: Product | E1: Category | F1: Region | G1: Quantity | H1: Unit Price | I1: Revenue
A2: ORD0001 | B2: 46085 | C2: =IF('Uncleaned Data'!C2="","Unknown",PROPER(TRIM(CLEAN(SUBSTITUTE('Uncleaned Data'!C2,CHAR(160)," "))))) -> Meena Joshi | D2: =IF('Uncleaned Data'!D2="","Unknown",PROPER(TRIM(CLEAN(SUBSTITUTE('Uncleaned Data'!D2,CHAR(160)," "))))) -> Smartphone | E2: =IF('Uncleaned Data'!E2="","Unknown",PROPER(TRIM(CLEAN(SUBSTITUTE('Uncleaned Data'!E2,CHAR(160)," "))))) -> Electronics | F2: =IF('Uncleaned Data'!F2="","Unknown",PROPER(TRIM(CLEAN(SUBSTITUTE('Uncleaned Data'!F2,CHAR(160)," "))))) -> South | G2: =IF('Uncleaned Data'!G2="","",IF('Uncleaned Data'!G2<=0,"", 'Uncleaned Data'!G2)) -> 1 | H2: =IF('Uncleaned Data'!H2="","",'Uncleaned Data'!H2) -> 29352.68 | I2: =IF(OR(G2="",H2=""),"",G2*H2) -> 29352.68
A3: ORD0002 | B3: 46131 | C3: =IF('Uncleaned Data'!C3="","Unknown",PROPER(TRIM(CLEAN(SUBSTITUTE('Uncleaned Data'!C3,CHAR(160)," "))))) -> Priya Reddy | D3: =IF('Uncleaned Data'!D3="","Unknown",PROPER(TRIM(CLEAN(SUBSTITUTE('Uncleaned Data'!D3,CHAR(160)," "))))) -> Smartphone | E3: =IF('Uncleaned Data'!E3="","Unknown",PROPER(TRIM(CLEAN(SUBSTITUTE('Uncleaned Data'!E3,CHAR(160)," "))))) -> Electronics | F3: =IF('Uncleaned Data'!F3="","Unknown",PROPER(TRIM(CLEAN(SUBSTITUTE('Uncleaned Data'!F3,CHAR(160)," "))))) -> North | G3: =IF('Uncleaned Data'!G3="","",IF('Uncleaned Data'!G3<=0,"", 'Uncleaned Data'!G3)) -> 5 | H3: =IF('Uncleaned Data'!H3="","",'Uncleaned Data'!H3) -> 25686.86 | I3: =IF(OR(G3="",H3=""),"",G3*H3) -> 128434.3
A4: ORD0003 | B4: 46177 | C4: =IF('Uncleaned Data'!C4="","Unknown",PROPER(TRIM(CLEAN(SUBSTITUTE('Uncleaned Data'!C4,CHAR(160)," "))))) -> Rahul Sharma | D4: =IF('Uncleaned Data'!D4="","Unknown",PROPER(TRIM(CLEAN(SUBSTITUTE('Uncleaned Data'!D4,CHAR(160)," "))))) -> Smartphone | E4: =IF('Uncleaned Data'!E4="","Unknown",PROPER(TRIM(CLEAN(SUBSTITUTE('Uncleaned Data'!E4,CHAR(160)," "))))) -> Electronics | F4: =IF('Uncleaned Data'!F4="","Unknown",PROPER(TRIM(CLEAN(SUBSTITUTE('Uncleaned Data'!F4,CHAR(160)," "))))) -> Central | G4: =IF('Uncleaned Data'!G4="","",IF('Uncleaned Data'!G4<=0,"", 'Uncleaned Data'!G4)) -> 2 | H4: =IF('Uncleaned Data'!H4="","",'Uncleaned Data'!H4) -> 26502.9 | I4: =IF(OR(G4="",H4=""),"",G4*H4) -> 53005.8
A5: ORD0004 | B5: 46137 | C5: =IF('Uncleaned Data'!C5="","Unknown",PROPER(TRIM(CLEAN(SUBSTITUTE('Uncleaned Data'!C5,CHAR(160)," "))))) -> Nikhil Jain | D5: =IF('Uncleaned Data'!D5="","Unknown",PROPER(TRIM(CLEAN(SUBSTITUTE('Uncleaned Data'!D5,CHAR(160)," "))))) -> Monitor | E5: =IF('Uncleaned Data'!E5="","Unknown",PROPER(TRIM(CLEAN(SUBSTITUTE('Uncleaned Data'!E5,CHAR(160)," "))))) -> Electronics | F5: =IF('Uncleaned Data'!F5="","Unknown",PROPER(TRIM(CLEAN(SUBSTITUTE('Uncleaned Data'!F5,CHAR(160)," "))))) -> East | G5: =IF('Uncleaned Data'!G5="","",IF('Uncleaned Data'!G5<=0,"", 'Uncleaned Data'!G5)) -> 5 | H5: =IF('Uncleaned Data'!H5="","",'Uncleaned Data'!H5) -> 14758.56 | I5: =IF(OR(G5="",H5=""),"",G5*H5) -> 73792.8
A6: ORD0005 | B6: 46110 | C6: =IF('Uncleaned Data'!C6="","Unknown",PROPER(TRIM(CLEAN(SUBSTITUTE('Uncleaned Data'!C6,CHAR(160)," "))))) -> Rohit Verma | D6: =IF('Uncleaned Data'!D6="","Unknown",PROPER(TRIM(CLEAN(SUBSTITUTE('Uncleaned Data'!D6,CHAR(160)," "))))) -> Unknown | E6: =IF('Uncleaned Data'!E6="","Unknown",PROPER(TRIM(CLEAN(SUBSTITUTE('Uncleaned Data'!E6,CHAR(160)," "))))) -> Electronics | F6: =IF('Uncleaned Data'!F6="","Unknown",PROPER(TRIM(CLEAN(SUBSTITUTE('Uncleaned Data'!F6,CHAR(160)," "))))) -> South | G6: =IF('Uncleaned Data'!G6="","",IF('Uncleaned Data'!G6<=0,"", 'Uncleaned Data'!G6)) -> 2 | H6: =IF('Uncleaned Data'!H6="","",'Uncleaned Data'!H6) -> 57179.53 | I6: =IF(OR(G6="",H6=""),"",G6*H6) -> 114359.06
A7: ORD0006 | B7: 46120 | C7: =IF('Uncleaned Data'!C7="","Unknown",PROPER(TRIM(CLEAN(SUBSTITUTE('Uncleaned Data'!C7,CHAR(160)," "))))) -> Sneha Patel | D7: =IF('Uncleaned Data'!D7="","Unknown",PROPER(TRIM(CLEAN(SUBSTITUTE('Uncleaned Data'!D7,CHAR(160)," "))))) -> Monitor | E7: =IF('Uncleaned Data'!E7="","Unknown",PROPER(TRIM(CLEAN(SUBSTITUTE('Uncleaned Data'!E7,CHAR(160)," "))))) -> Electronics | F7: =IF('Uncleaned Data'!F7="","Unknown",PROPER(TRIM(CLEAN(SUBSTITUTE('Uncleaned Data'!F7,CHAR(160)," "))))) -> East | G7: =IF('Uncleaned Data'!G7="","",IF('Uncleaned Data'!G7<=0,"", 'Uncleaned Data'!G7)) -> 3 | H7: =IF('Uncleaned Data'!H7="","",'Uncleaned Data'!H7) -> 13806.63 | I7: =IF(OR(G7="",H7=""),"",G7*H7) -> 41419.89
A8: ORD0007 | B8: 46034 | C8: =IF('Uncleaned Data'!C8="","Unknown",PROPER(TRIM(CLEAN(SUBSTITUTE('Uncleaned Data'!C8,CHAR(160)," "))))) -> Manoj Reddy | D8: =IF('Uncleaned Data'!D8="","Unknown",PROPER(TRIM(CLEAN(SUBSTITUTE('Uncleaned Data'!D8,CHAR(160)," "))))) -> Mouse | E8: =IF('Uncleaned Data'!E8="","Unknown",PROPER(TRIM(CLEAN(SUBSTITUTE('Uncleaned Data'!E8,CHAR(160)," "))))) -> Accessories | F8: =IF('Uncleaned Data'!F8="","Unknown",PROPER(TRIM(CLEAN(SUBSTITUTE('Uncleaned Data'!F8,CHAR(160)," "))))) -> Central | G8: =IF('Uncleaned Data'!G8="","",IF('Uncleaned Data'!G8<=0,"", 'Uncleaned Data'!G8)) -> 5 | H8: =IF('Uncleaned Data'!H8="","",'Uncleaned Data'!H8) -> 857.61 | I8: =IF(OR(G8="",H8=""),"",G8*H8) -> 4288.05
A9: ORD0008 | B9: 46098 | C9: =IF('Uncleaned Data'!C9="","Unknown",PROPER(TRIM(CLEAN(SUBSTITUTE('Uncleaned Data'!C9,CHAR(160)," "))))) -> Lakshmi Devi | D9: =IF('Uncleaned Data'!D9="","Unknown",PROPER(TRIM(CLEAN(SUBSTITUTE('Uncleaned Data'!D9,CHAR(160)," "))))) -> Smartphone | E9: =IF('Uncleaned Data'!E9="","Unknown",PROPER(TRIM(CLEAN(SUBSTITUTE('Uncleaned Data'!E9,CHAR(160)," "))))) -> Electronics | F9: =IF('Uncleaned Data'!F9="","Unknown",PROPER(TRIM(CLEAN(SUBSTITUTE('Uncleaned Data'!F9,CHAR(160)," "))))) -> East | G9: =IF('Uncleaned Data'!G9="","",IF('Uncleaned Data'!G9<=0,"", 'Uncleaned Data'!G9)) -> 4 | H9: =IF('Uncleaned Data'!H9="","",'Uncleaned Data'!H9) -> 25641.28 | I9: =IF(OR(G9="",H9=""),"",G9*H9) -> 102565.12
A10: ORD0009 | B10: 46034 | C10: =IF('Uncleaned Data'!C10="","Unknown",PROPER(TRIM(CLEAN(SUBSTITUTE('Uncleaned Data'!C10,CHAR(160)," "))))) -> Meena Joshi | D10: =IF('Uncleaned Data'!D10="","Unknown",PROPER(TRIM(CLEAN(SUBSTITUTE('Uncleaned Data'!D10,CHAR(160)," "))))) -> Printer | E10: =IF('Uncleaned Data'!E10="","Unknown",PROPER(TRIM(CLEAN(SUBSTITUTE('Uncleaned Data'!E10,CHAR(160)," "))))) -> Electronics | F10: =IF('Uncleaned Data'!F10="","Unknown",PROPER(TRIM(CLEAN(SUBSTITUTE('Uncleaned Data'!F10,CHAR(160)," "))))) -> East | G10: =IF('Uncleaned Data'!G10="","",IF('Uncleaned Data'!G10<=0,"", 'Uncleaned Data'!G10)) -> 2 | H10: =IF('Uncleaned Data'!H10="","",'Uncleaned Data'!H10) -> 12490.97 | I10: =IF(OR(G10="",H10=""),"",G10*H10) -> 24981.94
A11: ORD0010 | B11: 46120 | C11: =IF('Uncleaned Data'!C11="","Unknown",PROPER(TRIM(CLEAN(SUBSTITUTE('Uncleaned Data'!C11,CHAR(160)," "))))) -> Rohit Verma | D11: =IF('Uncleaned Data'!D11="","Unknown",PROPER(TRIM(CLEAN(SUBSTITUTE('Uncleaned Data'!D11,CHAR(160)," "))))) -> Smartphone | E11: =IF('Uncleaned Data'!E11="","Unknown",PROPER(TRIM(CLEAN(SUBSTITUTE('Uncleaned Data'!E11,CHAR(160)," "))))) -> Electronics | F11: =IF('Uncleaned Data'!F11="","Unknown",PROPER(TRIM(CLEAN(SUBSTITUTE('Uncleaned Data'!F11,CHAR(160)," "))))) -> West | G11: =IF('Uncleaned Data'!G11="","",IF('Uncleaned Data'!G11<=0,"", 'Uncleaned Data'!G11)) -> 2 | H11: =IF('Uncleaned Data'!H11="","",'Uncleaned Data'!H11) -> 30052.31 | I11: =IF(OR(G11="",H11=""),"",G11*H11) -> 60104.62
A12: ORD0011 | B12: 46076 | C12: =IF('Uncleaned Data'!C12="","Unknown",PROPER(TRIM(CLEAN(SUBSTITUTE('Uncleaned Data'!C12,CHAR(160)," "))))) -> Rohit Verma | D12: =IF('Uncleaned Data'!D12="","Unknown",PROPER(TRIM(CLEAN(SUBSTITUTE('Uncleaned Data'!D12,CHAR(160)," "))))) -> Mouse | E12: =IF('Uncleaned Data'!E12="","Unknown",PROPER(TRIM(CLEAN(SUBSTITUTE('Uncleaned Data'!E12,CHAR(160)," "))))) -> Unknown | F12: =IF('Uncleaned Data'!F12="","Unknown",PROPER(TRIM(CLEAN(SUBSTITUTE('Uncleaned Data'!F12,CHAR(160)," "))))) -> North | G12: =IF('Uncleaned Data'!G12="","",IF('Uncleaned Data'!G12<=0,"", 'Uncleaned Data'!G12)) -> 2 | H12: =IF('Uncleaned Data'!H12="","",'Uncleaned Data'!H12) -> 876.63 | I12: =IF(OR(G12="",H12=""),"",G12*H12) -> 1753.26
A13: ORD0012 | B13: 46085 | C13: =IF('Uncleaned Data'!C13="","Unknown",PROPER(TRIM(CLEAN(SUBSTITUTE('Uncleaned Data'!C13,CHAR(160)," "))))) -> Ananya Rao | D13: =IF('Uncleaned Data'!D13="","Unknown",PROPER(TRIM(CLEAN(SUBSTITUTE('Uncleaned Data'!D13,CHAR(160)," "))))) -> Printer | E13: =IF('Uncleaned Data'!E13="","Unknown",PROPER(TRIM(CLEAN(SUBSTITUTE('Uncleaned Data'!E13,CHAR(160)," "))))) -> Electronics | F13: =IF('Uncleaned Data'!F13="","Unknown",PROPER(TRIM(CLEAN(SUBSTITUTE('Uncleaned Data'!F13,CHAR(160)," "))))) -> West | G13: =IF('Uncleaned Data'!G13="","",IF('Uncleaned Data'!G13<=0,"", 'Uncleaned Data'!G13)) -> 2 | H13: =IF('Uncleaned Data'!H13="","",'Uncleaned Data'!H13) -> 12081.94 | I13: =IF(OR(G13="",H13=""),"",G13*H13) -> 24163.88
... A121: ORD0120 | B121: 46235 | C121: =IF('Uncleaned Data'!C121="","Unknown",PROPER(TRIM(CLEAN(SUBSTITUTE('Uncleaned Data'!C121,CHAR(160)," "))))) -> Manoj Reddy | D121: =IF('Uncleaned Data'!D121="","Unknown",PROPER(TRIM(CLEAN(SUBSTITUTE('Uncleaned Data'!D121,CHAR(160)," "))))) -> Office Chair | E121: =IF('Uncleaned Data'!E121="","Unknown",PROPER(TRIM(CLEAN(SUBSTITUTE('Uncleaned Data'!E121,CHAR(160)," "))))) -> Furniture | F121: =IF('Uncleaned Data'!F121="","Unknown",PROPER(TRIM(CLEAN(SUBSTITUTE('Uncleaned Data'!F121,CHAR(160)," "))))) -> South | G121: =IF('Uncleaned Data'!G121="","",IF('Uncleaned Data'!G121<=0,"", 'Uncleaned Data'!G121)) -> 3 | H121: =IF('Uncleaned Data'!H121="","",'Uncleaned Data'!H121) -> 8730.49 | I121: =IF(OR(G121="",H121=""),"",G121*H121) -> 26191.47

Sheet Cleaned Data
A1: Order ID | B1: Order Date | C1: Customer Name | D1: Product | E1: Category | F1: Region | G1: Quantity | H1: Unit Price | I1: Revenue
A2: ORD0001 | B2: 46085 | C2: =IF('Uncleaned Data'!C2="","Unknown",PROPER(TRIM(CLEAN(SUBSTITUTE('Uncleaned Data'!C2,CHAR(160)," "))))) -> Meena Joshi | D2: =IF('Uncleaned Data'!D2="","Unknown",PROPER(TRIM(CLEAN(SUBSTITUTE('Uncleaned Data'!D2,CHAR(160)," "))))) -> Smartphone | E2: =IF('Uncleaned Data'!E2="","Unknown",PROPER(TRIM(CLEAN(SUBSTITUTE('Uncleaned Data'!E2,CHAR(160)," "))))) -> Electronics | F2: =IF('Uncleaned Data'!F2="","Unknown",PROPER(TRIM(CLEAN(SUBSTITUTE('Uncleaned Data'!F2,CHAR(160)," "))))) -> South | G2: =IF('Uncleaned Data'!G2="","",IF('Uncleaned Data'!G2<=0,"", 'Uncleaned Data'!G2)) -> 1 | H2: =IF('Uncleaned Data'!H2="","",'Uncleaned Data'!H2) -> 29352.68 | I2: =IF(OR(G2="",H2=""),"",G2*H2) -> 29352.68
A3: ORD0002 | B3: 46131 | C3: =IF('Uncleaned Data'!C3="","Unknown",PROPER(TRIM(CLEAN(SUBSTITUTE('Uncleaned Data'!C3,CHAR(160)," "))))) -> Priya Reddy | D3: =IF('Uncleaned Data'!D3="","Unknown",PROPER(TRIM(CLEAN(SUBSTITUTE('Uncleaned Data'!D3,CHAR(160)," "))))) -> Smartphone | E3: =IF('Uncleaned Data'!E3="","Unknown",PROPER(TRIM(CLEAN(SUBSTITUTE('Uncleaned Data'!E3,CHAR(160)," "))))) -> Electronics | F3: =IF('Uncleaned Data'!F3="","Unknown",PROPER(TRIM(CLEAN(SUBSTITUTE('Uncleaned Data'!F3,CHAR(160)," "))))) -> North | G3: =IF('Uncleaned Data'!G3="","",IF('Uncleaned Data'!G3<=0,"", 'Uncleaned Data'!G3)) -> 5 | H3: =IF('Uncleaned Data'!H3="","",'Uncleaned Data'!H3) -> 25686.86 | I3: =IF(OR(G3="",H3=""),"",G3*H3) -> 128434.3
A4: ORD0003 | B4: 46177 | C4: =IF('Uncleaned Data'!C4="","Unknown",PROPER(TRIM(CLEAN(SUBSTITUTE('Uncleaned Data'!C4,CHAR(160)," "))))) -> Rahul Sharma | D4: =IF('Uncleaned Data'!D4="","Unknown",PROPER(TRIM(CLEAN(SUBSTITUTE('Uncleaned Data'!D4,CHAR(160)," "))))) -> Smartphone | E4: =IF('Uncleaned Data'!E4="","Unknown",PROPER(TRIM(CLEAN(SUBSTITUTE('Uncleaned Data'!E4,CHAR(160)," "))))) -> Electronics | F4: =IF('Uncleaned Data'!F4="","Unknown",PROPER(TRIM(CLEAN(SUBSTITUTE('Uncleaned Data'!F4,CHAR(160)," "))))) -> Central | G4: =IF('Uncleaned Data'!G4="","",IF('Uncleaned Data'!G4<=0,"", 'Uncleaned Data'!G4)) -> 2 | H4: =IF('Uncleaned Data'!H4="","",'Uncleaned Data'!H4) -> 26502.9 | I4: =IF(OR(G4="",H4=""),"",G4*H4) -> 53005.8
A5: ORD0004 | B5: 46137 | C5: =IF('Uncleaned Data'!C5="","Unknown",PROPER(TRIM(CLEAN(SUBSTITUTE('Uncleaned Data'!C5,CHAR(160)," "))))) -> Nikhil Jain | D5: =IF('Uncleaned Data'!D5="","Unknown",PROPER(TRIM(CLEAN(SUBSTITUTE('Uncleaned Data'!D5,CHAR(160)," "))))) -> Monitor | E5: =IF('Uncleaned Data'!E5="","Unknown",PROPER(TRIM(CLEAN(SUBSTITUTE('Uncleaned Data'!E5,CHAR(160)," "))))) -> Electronics | F5: =IF('Uncleaned Data'!F5="","Unknown",PROPER(TRIM(CLEAN(SUBSTITUTE('Uncleaned Data'!F5,CHAR(160)," "))))) -> East | G5: =IF('Uncleaned Data'!G5="","",IF('Uncleaned Data'!G5<=0,"", 'Uncleaned Data'!G5)) -> 5 | H5: =IF('Uncleaned Data'!H5="","",'Uncleaned Data'!H5) -> 14758.56 | I5: =IF(OR(G5="",H5=""),"",G5*H5) -> 73792.8
A6: ORD0005 | B6: 46110 | C6: =IF('Uncleaned Data'!C6="","Unknown",PROPER(TRIM(CLEAN(SUBSTITUTE('Uncleaned Data'!C6,CHAR(160)," "))))) -> Rohit Verma | D6: =IF('Uncleaned Data'!D6="","Unknown",PROPER(TRIM(CLEAN(SUBSTITUTE('Uncleaned Data'!D6,CHAR(160)," "))))) -> Unknown | E6: =IF('Uncleaned Data'!E6="","Unknown",PROPER(TRIM(CLEAN(SUBSTITUTE('Uncleaned Data'!E6,CHAR(160)," "))))) -> Electronics | F6: =IF('Uncleaned Data'!F6="","Unknown",PROPER(TRIM(CLEAN(SUBSTITUTE('Uncleaned Data'!F6,CHAR(160)," "))))) -> South | G6: =IF('Uncleaned Data'!G6="","",IF('Uncleaned Data'!G6<=0,"", 'Uncleaned Data'!G6)) -> 2 | H6: =IF('Uncleaned Data'!H6="","",'Uncleaned Data'!H6) -> 57179.53 | I6: =IF(OR(G6="",H6=""),"",G6*H6) -> 114359.06
A7: ORD0006 | B7: 46120 | C7: =IF('Uncleaned Data'!C7="","Unknown",PROPER(TRIM(CLEAN(SUBSTITUTE('Uncleaned Data'!C7,CHAR(160)," "))))) -> Sneha Patel | D7: =IF('Uncleaned Data'!D7="","Unknown",PROPER(TRIM(CLEAN(SUBSTITUTE('Uncleaned Data'!D7,CHAR(160)," "))))) -> Monitor | E7: =IF('Uncleaned Data'!E7="","Unknown",PROPER(TRIM(CLEAN(SUBSTITUTE('Uncleaned Data'!E7,CHAR(160)," "))))) -> Electronics | F7: =IF('Uncleaned Data'!F7="","Unknown",PROPER(TRIM(CLEAN(SUBSTITUTE('Uncleaned Data'!F7,CHAR(160)," "))))) -> East | G7: =IF('Uncleaned Data'!G7="","",IF('Uncleaned Data'!G7<=0,"", 'Uncleaned Data'!G7)) -> 3 | H7: =IF('Uncleaned Data'!H7="","",'Uncleaned Data'!H7) -> 13806.63 | I7: =IF(OR(G7="",H7=""),"",G7*H7) -> 41419.89
A8: ORD0007 | B8: 46034 | C8: =IF('Uncleaned Data'!C8="","Unknown",PROPER(TRIM(CLEAN(SUBSTITUTE('Uncleaned Data'!C8,CHAR(160)," "))))) -> Manoj Reddy | D8: =IF('Uncleaned Data'!D8="","Unknown",PROPER(TRIM(CLEAN(SUBSTITUTE('Uncleaned Data'!D8,CHAR(160)," "))))) -> Mouse | E8: =IF('Uncleaned Data'!E8="","Unknown",PROPER(TRIM(CLEAN(SUBSTITUTE('Uncleaned Data'!E8,CHAR(160)," "))))) -> Accessories | F8: =IF('Uncleaned Data'!F8="","Unknown",PROPER(TRIM(CLEAN(SUBSTITUTE('Uncleaned Data'!F8,CHAR(160)," "))))) -> Central | G8: =IF('Uncleaned Data'!G8="","",IF('Uncleaned Data'!G8<=0,"", 'Uncleaned Data'!G8)) -> 5 | H8: =IF('Uncleaned Data'!H8="","",'Uncleaned Data'!H8) -> 857.61 | I8: =IF(OR(G8="",H8=""),"",G8*H8) -> 4288.05
A9: ORD0008 | B9: 46098 | C9: =IF('Uncleaned Data'!C9="","Unknown",PROPER(TRIM(CLEAN(SUBSTITUTE('Uncleaned Data'!C9,CHAR(160)," "))))) -> Lakshmi Devi | D9: =IF('Uncleaned Data'!D9="","Unknown",PROPER(TRIM(CLEAN(SUBSTITUTE('Uncleaned Data'!D9,CHAR(160)," "))))) -> Smartphone | E9: =IF('Uncleaned Data'!E9="","Unknown",PROPER(TRIM(CLEAN(SUBSTITUTE('Uncleaned Data'!E9,CHAR(160)," "))))) -> Electronics | F9: =IF('Uncleaned Data'!F9="","Unknown",PROPER(TRIM(CLEAN(SUBSTITUTE('Uncleaned Data'!F9,CHAR(160)," "))))) -> East | G9: =IF('Uncleaned Data'!G9="","",IF('Uncleaned Data'!G9<=0,"", 'Uncleaned Data'!G9)) -> 4 | H9: =IF('Uncleaned Data'!H9="","",'Uncleaned Data'!H9) -> 25641.28 | I9: =IF(OR(G9="",H9=""),"",G9*H9) -> 102565.12
A10: ORD0009 | B10: 46034 | C10: =IF('Uncleaned Data'!C10="","Unknown",PROPER(TRIM(CLEAN(SUBSTITUTE('Uncleaned Data'!C10,CHAR(160)," "))))) -> Meena Joshi | D10: =IF('Uncleaned Data'!D10="","Unknown",PROPER(TRIM(CLEAN(SUBSTITUTE('Uncleaned Data'!D10,CHAR(160)," "))))) -> Printer | E10: =IF('Uncleaned Data'!E10="","Unknown",PROPER(TRIM(CLEAN(SUBSTITUTE('Uncleaned Data'!E10,CHAR(160)," "))))) -> Electronics | F10: =IF('Uncleaned Data'!F10="","Unknown",PROPER(TRIM(CLEAN(SUBSTITUTE('Uncleaned Data'!F10,CHAR(160)," "))))) -> East | G10: =IF('Uncleaned Data'!G10="","",IF('Uncleaned Data'!G10<=0,"", 'Uncleaned Data'!G10)) -> 2 | H10: =IF('Uncleaned Data'!H10="","",'Uncleaned Data'!H10) -> 12490.97 | I10: =IF(OR(G10="",H10=""),"",G10*H10) -> 24981.94
A11: ORD0010 | B11: 46120 | C11: =IF('Uncleaned Data'!C11="","Unknown",PROPER(TRIM(CLEAN(SUBSTITUTE('Uncleaned Data'!C11,CHAR(160)," "))))) -> Rohit Verma | D11: =IF('Uncleaned Data'!D11="","Unknown",PROPER(TRIM(CLEAN(SUBSTITUTE('Uncleaned Data'!D11,CHAR(160)," "))))) -> Smartphone | E11: =IF('Uncleaned Data'!E11="","Unknown",PROPER(TRIM(CLEAN(SUBSTITUTE('Uncleaned Data'!E11,CHAR(160)," "))))) -> Electronics | F11: =IF('Uncleaned Data'!F11="","Unknown",PROPER(TRIM(CLEAN(SUBSTITUTE('Uncleaned Data'!F11,CHAR(160)," "))))) -> West | G11: =IF('Uncleaned Data'!G11="","",IF('Uncleaned Data'!G11<=0,"", 'Uncleaned Data'!G11)) -> 2 | H11: =IF('Uncleaned Data'!H11="","",'Uncleaned Data'!H11) -> 30052.31 | I11: =IF(OR(G11="",H11=""),"",G11*H11) -> 60104.62
A12: ORD0011 | B12: 46076 | C12: =IF('Uncleaned Data'!C12="","Unknown",PROPER(TRIM(CLEAN(SUBSTITUTE('Uncleaned Data'!C12,CHAR(160)," "))))) -> Rohit Verma | D12: =IF('Uncleaned Data'!D12="","Unknown",PROPER(TRIM(CLEAN(SUBSTITUTE('Uncleaned Data'!D12,CHAR(160)," "))))) -> Mouse | E12: =IF('Uncleaned Data'!E12="","Unknown",PROPER(TRIM(CLEAN(SUBSTITUTE('Uncleaned Data'!E12,CHAR(160)," "))))) -> Unknown | F12: =IF('Uncleaned Data'!F12="","Unknown",PROPER(TRIM(CLEAN(SUBSTITUTE('Uncleaned Data'!F12,CHAR(160)," "))))) -> North | G12: =IF('Uncleaned Data'!G12="","",IF('Uncleaned Data'!G12<=0,"", 'Uncleaned Data'!G12)) -> 2 | H12: =IF('Uncleaned Data'!H12="","",'Uncleaned Data'!H12) -> 876.63 | I12: =IF(OR(G12="",H12=""),"",G12*H12) -> 1753.26
A13: ORD0012 | B13: 46085 | C13: =IF('Uncleaned Data'!C13="","Unknown",PROPER(TRIM(CLEAN(SUBSTITUTE('Uncleaned Data'!C13,CHAR(160)," "))))) -> Ananya Rao | D13: =IF('Uncleaned Data'!D13="","Unknown",PROPER(TRIM(CLEAN(SUBSTITUTE('Uncleaned Data'!D13,CHAR(160)," "))))) -> Printer | E13: =IF('Uncleaned Data'!E13="","Unknown",PROPER(TRIM(CLEAN(SUBSTITUTE('Uncleaned Data'!E13,CHAR(160)," "))))) -> Electronics | F13: =IF('Uncleaned Data'!F13="","Unknown",PROPER(TRIM(CLEAN(SUBSTITUTE('Uncleaned Data'!F13,CHAR(160)," "))))) -> West | G13: =IF('Uncleaned Data'!G13="","",IF('Uncleaned Data'!G13<=0,"", 'Uncleaned Data'!G13)) -> 2 | H13: =IF('Uncleaned Data'!H13="","",'Uncleaned Data'!H13) -> 12081.94 | I13: =IF(OR(G13="",H13=""),"",G13*H13) -> 24163.88
... A121: ORD0120 | B121: 46235 | C121: =IF('Uncleaned Data'!C121="","Unknown",PROPER(TRIM(CLEAN(SUBSTITUTE('Uncleaned Data'!C121,CHAR(160)," "))))) -> Manoj Reddy | D121: =IF('Uncleaned Data'!D121="","Unknown",PROPER(TRIM(CLEAN(SUBSTITUTE('Uncleaned Data'!D121,CHAR(160)," "))))) -> Office Chair | E121: =IF('Uncleaned Data'!E121="","Unknown",PROPER(TRIM(CLEAN(SUBSTITUTE('Uncleaned Data'!E121,CHAR(160)," "))))) -> Furniture | F121: =IF('Uncleaned Data'!F121="","Unknown",PROPER(TRIM(CLEAN(SUBSTITUTE('Uncleaned Data'!F121,CHAR(160)," "))))) -> South | G121: =IF('Uncleaned Data'!G121="","",IF('Uncleaned Data'!G121<=0,"", 'Uncleaned Data'!G121)) -> 3 | H121: =IF('Uncleaned Data'!H121="","",'Uncleaned Data'!H121) -> 8730.49 | I121: =IF(OR(G121="",H121=""),"",G121*H121) -> 26191.47
