Workbook
Name Slicer_Category: #N/A
Name Slicer_Months__Order_Date: #N/A
Name Slicer_Product: #N/A
Name Slicer_Region: #N/A

Sheet RawData
A1: Order_ID | B1: Order_Date | C1: Region | D1: City | E1: Product | F1: Category | G1: Quantity | H1: Unit_Price | I1: Discount | J1: Revenue | K1: Cost | L1: Profit
A2: ORD0001 | B2: 45985 | C2: North | D2: Delhi | E2: Laptop | F2: Electronics | G2: 5 | H2: 818.01 | I2: 0.02 | J2: 4008.25 | K2: 3233.43 | L2: 774.82
A3: ORD0002 | B3: 45729 | C3: North | D3: Lucknow | E3: Backpack | F3: Accessories | G3: 9 | H3: 48.13 | I3: 0 | J3: 433.17 | K3: 308.26 | L3: 124.91
A4: ORD0003 | B4: 45874 | C4: North | D4: Delhi | E4: Laptop | F4: Electronics | G4: 2 | H4: 762.28 | I4: 0.02 | J4: 1494.07 | K4: 884.67 | L4: 609.4
A5: ORD0004 | B5: 45916 | C5: North | D5: Lucknow | E5: Notebook | F5: Office Supplies | G5: 4 | H5: 6.94 | I5: 0.2 | J5: 22.21 | K5: 17.41 | L5: 4.8
A6: ORD0005 | B6: 46017 | C6: West | D6: Pune | E6: Monitor | F6: Electronics | G6: 8 | H6: 226.67 | I6: 0.15 | J6: 1541.36 | K6: 1142.42 | L6: 398.94
A7: ORD0006 | B7: 45661 | C7: South | D7: Chennai | E7: Keyboard | F7: Accessories | G7: 7 | H7: 29.97 | I7: 0.05 | J7: 199.3 | K7: 161.81 | L7: 37.49
A8: ORD0007 | B8: 45737 | C8: South | D8: Chennai | E8: Desk | F8: Furniture | G8: 2 | H8: 274.93 | I8: 0 | J8: 549.86 | K8: 333.95 | L8: 215.91
A9: ORD0008 | B9: 45707 | C9: East | D9: Hyderabad | E9: Desk | F9: Furniture | G9: 10 | H9: 226.14 | I9: 0.05 | J9: 2148.33 | K9: 1287.97 | L9: 860.36
A10: ORD0009 | B10: 45893 | C10: North | D10: Jaipur | E10: Bookshelf | F10: Furniture | G10: 2 | H10: 131.78 | I10: 0.15 | J10: 224.03 | K10: 154.96 | L10: 69.07
A11: ORD0010 | B11: 45979 | C11: East | D11: Kolkata | E11: Pen Set | F11: Office Supplies | G11: 4 | H11: 11.76 | I11: 0.2 | J11: 37.63 | K11: 23.66 | L11: 13.97
A12: ORD0011 | B12: 45681 | C12: South | D12: Hyderabad | E12: Office Chair | F12: Furniture | G12: 2 | H12: 186.04 | I12: 0.02 | J12: 364.64 | K12: 214.29 | L12: 150.35
A13: ORD0012 | B13: 45852 | C13: East | D13: Bhubaneswar | E13: Printer | F13: Office Supplies | G13: 6 | H13: 150.02 | I13: 0.02 | J13: 882.12 | K13: 572.42 | L13: 309.7
... A52: ORD0051 | B52: 45687 | C52: North | D52: Delhi | E52: Keyboard | F52: Accessories | G52: 6 | H52: 30.08 | I52: 0 | J52: 180.48 | K52: 130.28 | L52: 50.2
A53: ORD0052 | B53: 45957 | C53: West | D53: Mumbai | E53: Notebook | F53: Office Supplies | H53: 7.55 | I53: 0.02 | J53: 66.59 | K53: 45.77 | L53: 20.82
A54: ORD0053 | B54: 45918 | C54: North | D54: Delhi | E54: Headphones | F54: Electronics | G54: 2 | H54: 89.78 | I54: 0.15 | J54: 152.63 | K54: 94.22 | L54: 58.41
A55: ORD0054 | B55: 46003 | C55: South | D55: Hyderabad | E55: Bookshelf | F55: Furniture | G55: 2 | H55: 136.24 | I55: 0.15 | J55: 231.61 | K55: 174.63 | L55: 56.98
A56: ORD0055 | B56: 45954 | C56: North | D56: Lucknow | E56: Pen Set | F56: Office Supplies | G56: 2 | H56: 11.02 | I56: 0.1 | J56: 19.84 | K56: 11.32 | L56: 8.52
A57: ORD0056 | B57: 45956 | C57: East | D57: Patna | E57: Office Chair | F57: Furniture | G57: 4 | H57: 168.65 | I57: 0.2 | J57: 539.68 | K57: 320.32 | L57: 219.36
A58: ORD0057 | B58: 45818 | C58: South | D58: Bengaluru | E58: Office Chair | F58: Furniture | G58: 7 | H58: 203.2 | I58: 0.02 | J58: 1393.95 | K58: 1070.82 | L58: 323.13
A59: ORD0058 | B59: 45988 | C59: East | D59: Kolkata | E59: Printer | F59: Office Supplies | G59: 6 | H59: 166.4 | I59: 0 | J59: 998.4 | K59: 784.04 | L59: 214.36
A60: ORD0059 | B60: 45892 | C60: North | D60: Lucknow | E60: Smartphone | F60: Electronics | G60: 9 | H60: 600.11 | I60: 0.02 | J60: 5292.97 | K60: 3177.76 | L60: 2115.21
A61: ORD0060 | B61: 45793 | C61: South | D61: Chennai | E61: Desk | F61: Furniture | G61: 2 | H61: 279.44 | I61: 0.02 | J61: 547.7 | K61: 380.99 | L61: 166.71
A62: ORD0061 | B62: 45803 | C62: South | D62: Chennai | E62: Printer | F62: Office Supplies | G62: 9 | H62: 174.76 | I62: 0.2 | J62: 1258.27 | K62: 996.48 | L62: 261.79
A63: ORD0062 | B63: 45971 | C63: North | D63: Lucknow | E63: Backpack | F63: Accessories | G63: 9 | H63: 42.54 | I63: 0.05 | J63: 363.72 | K63: 210.85 | L63: 152.87
A64: ORD0063 | B64: 45711 | C64: South | D64: Bengaluru | E64: Office Chair | F64: Furniture | G64: 2 | H64: 165.31 | I64: 0 | J64: 330.62 | K64: 219.97 | L64: 110.65
A65: ORD0064 | B65: 45941 | C65: South | D65: Hyderabad | E65: Office Chair | F65: Furniture | G65: 5 | H65: 197.17 | I65: 0.15 | J65: 837.97 | K65: 655.63 | L65: 182.34
... A69: ORD0068 | B69: 45884 | C69: West | D69: Mumbai | E69: Notebook | F69: Office Supplies | G69: 1 | H69: 9.06 | I69: 0 | J69: 9.06 | K69: 5.77 | L69: 3.29
A70: ORD0069 | B70: 46011 | C70: South | D70: Bengaluru | E70: Notebook | F70: Office Supplies | G70: 1 | H70: 8.05 | J70: 7.65 | K70: 5.66 | L70: 1.99
A71: ORD0070 | B71: 45940 | C71: South | D71: Chennai | E71: Bookshelf | F71: Furniture | G71: 3 | H71: 134.27 | I71: 0 | J71: 402.81 | K71: 327.24 | L71: 75.57
A72: ORD0071 | B72: 45844 | C72: North | D72: Delhi | E72: Desk | F72: Furniture | G72: 4 | H72: 284.68 | I72: 0.2 | J72: 910.98 | K72: 562.97 | L72: 348.01
A73: ORD0072 | B73: 45999 | C73: North | D73: Lucknow | E73: Desk | F73: Furniture | G73: 9 | H73: 249.79 | I73: 0.1 | J73: 2023.3 | K73: 1277.18 | L73: 746.12
A74: ORD0073 | B74: 45737 | C74: South | D74: Hyderabad | E74: Headphones | F74: Electronics | G74: 3 | H74: 74.84 | I74: 0.1 | J74: 202.07 | K74: 113.15 | L74: 88.92
A75: ORD0074 | B75: 45749 | C75: East | D75: Kolkata | E75: Bookshelf | F75: Furniture | G75: 4 | H75: 144.6 | I75: 0.05 | J75: 549.48 | K75: 376.79 | L75: 172.69
A76: ORD0075 | B76: 46017 | C76: North | D76: Delhi | E76: Bookshelf | F76: Furniture | G76: 1 | H76: 121.16 | I76: 0.1 | J76: 109.04 | K76: 68.18 | L76: 40.86
A77: ORD0076 | B77: 45760 | C77: West | D77: Mumbai | E77: Desk | F77: Furniture | G77: 5 | H77: 280.62 | I77: 0.02 | J77: 1375.04 | K77: 845.21 | L77: 529.83
A78: ORD0077 | B78: 45670 | C78: South | D78: Hyderabad | E78: Bookshelf | F78: Furniture | G78: 6 | H78: 125.09 | I78: 0.05 | J78: 713.01 | K78: 486.38 | L78: 226.63
A79: ORD0078 | B79: 45800 | C79: East | D79: Patna | E79: Backpack | F79: Accessories | G79: 9 | H79: 51.56 | I79: 0.1 | J79: 417.64 | K79: 257 | L79: 160.64
A80: ORD0079 | B80: 45932 | C80: East | D80: Kolkata | E80: Laptop | F80: Electronics | G80: 2 | H80: 893.89 | I80: 0.05 | J80: 1698.39 | K80: 1283.37 | L80: 415.02
A81: ORD0080 | B81: 45955 | C81: East | D81: Bhubaneswar | E81: Laptop | F81: Electronics | G81: 2 | H81: 783.1 | I81: 0.15 | J81: 1331.27 | K81: 993.95 | L81: 337.32
...

Sheet Cleaned Data
A1: Order_ID | B1: Order_Date | C1: Region | D1: City | E1: Product | F1: Category | G1: Quantity | H1: Unit_Price | I1: Discount | J1: Revenue | K1: Cost | L1: Profit
A2: ORD0001 | B2: 45985 | C2: =IF(RawData!C2="","Unknown",PROPER(TRIM(CLEAN(SUBSTITUTE(RawData!C2,CHAR(160)," "))))) -> North | D2: =IF(RawData!D2="","Unknown",PROPER(TRIM(CLEAN(SUBSTITUTE(RawData!D2,CHAR(160)," "))))) -> Delhi | E2: =IF(RawData!E2="","Unknown",PROPER(TRIM(CLEAN(SUBSTITUTE(RawData!E2,CHAR(160)," "))))) -> Laptop | F2: =IF(RawData!F2="","Unknown",PROPER(TRIM(CLEAN(SUBSTITUTE(RawData!F2,CHAR(160)," "))))) -> Electronics | G2: =_xlfn.LET( _xlpm.q,RawData!G2, _xlpm.u,RawData!H2, _xlpm.d,RawData!I2, _xlpm.r,RawData!J2, IF(AND(ISNUMBER(_xlpm.q),_xlpm.q>0),_xlpm.q, IF(AND(ISNUMBER(_xlpm.r),ISNUMBER(_xlpm.u),_xlpm.u>0,ISNUMBER(_xlpm.d),_xlpm.d>=0,_xlpm.d<1), ROUND(_xlpm.r/(_xlpm.u*(1-_xlpm.d)),0), "" ) ) ) -> 5 | H2: =_xlfn.LET( _xlpm.q,RawData!G2, _xlpm.u,RawData!H2, _xlpm.d,RawData!I2, _xlpm.r,RawData!J2, IF(AND(ISNUMBER(_xlpm.u),_xlpm.u>0),_xlpm.u, IF(AND(ISNUMBER(_xlpm.q),_xlpm.q>0,ISNUMBER(_xlpm.r),ISNUMBER(_xlpm.d),_xlpm.d>=0,_xlpm.d<1), _xlpm.r/(_xlpm.q*(1-_xlpm.d)), "" ) ) ) -> 818.01 | I2: =_xlfn.LET( _xlpm.q,RawData!G2, _xlpm.u,RawData!H2, _xlpm.d,RawData!I2, _xlpm.r,RawData!J2, IF(AND(ISNUMBER(_xlpm.d),_xlpm.d>=0,_xlpm.d<1),_xlpm.d, IF(AND(ISNUMBER(_xlpm.q),_xlpm.q>0,ISNUMBER(_xlpm.u),_xlpm.u>0,ISNUMBER(_xlpm.r),_xlpm.r>=0), 1-(_xlpm.r/(_xlpm.q*_xlpm.u)), "" ) ) ) -> 0.02 | J2: =_xlfn.LET( _xlpm.q,RawData!G2, _xlpm.u,RawData!H2, _xlpm.d,RawData!I2, _xlpm.r,RawData!J2, IF(AND(ISNUMBER(_xlpm.r),_xlpm.r>=0),_xlpm.r, IF(AND(ISNUMBER(_xlpm.q),_xlpm.q>0,ISNUMBER(_xlpm.u),_xlpm.u>0,ISNUMBER(_xlpm.d),_xlpm.d>=0,_xlpm.d<1), _xlpm.q*_xlpm.u*(1-_xlpm.d), "" ) ) ) -> 4008.25 | K2: =_xlfn.LET( _xlpm.c,RawData!K2, _xlpm.r,RawData!J2, _xlpm.p,RawData!L2, IF(AND(ISNUMBER(_xlpm.c),_xlpm.c>=0),_xlpm.c, IF(AND(ISNUMBER(_xlpm.r),ISNUMBER(_xlpm.p)), _xlpm.r-_xlpm.p, "" ) ) ) -> 3233.43 | L2: =_xlfn.LET( _xlpm.p,RawData!L2, _xlpm.r,RawData!J2, _xlpm.c,RawData!K2, IF(ISNUMBER(_xlpm.p),_xlpm.p, IF(AND(ISNUMBER(_xlpm.r),ISNUMBER(_xlpm.c)), _xlpm.r-_xlpm.c, "" ) )) -> 774.82
A3: ORD0002 | B3: 45729 | C3: =IF(RawData!C3="","Unknown",PROPER(TRIM(CLEAN(SUBSTITUTE(RawData!C3,CHAR(160)," "))))) -> North | D3: =IF(RawData!D3="","Unknown",PROPER(TRIM(CLEAN(SUBSTITUTE(RawData!D3,CHAR(160)," "))))) -> Lucknow | E3: =IF(RawData!E3="","Unknown",PROPER(TRIM(CLEAN(SUBSTITUTE(RawData!E3,CHAR(160)," "))))) -> Backpack | F3: =IF(RawData!F3="","Unknown",PROPER(TRIM(CLEAN(SUBSTITUTE(RawData!F3,CHAR(160)," "))))) -> Accessories | G3: =_xlfn.LET( _xlpm.q,RawData!G3, _xlpm.u,RawData!H3, _xlpm.d,RawData!I3, _xlpm.r,RawData!J3, IF(AND(ISNUMBER(_xlpm.q),_xlpm.q>0),_xlpm.q, IF(AND(ISNUMBER(_xlpm.r),ISNUMBER(_xlpm.u),_xlpm.u>0,ISNUMBER(_xlpm.d),_xlpm.d>=0,_xlpm.d<1), ROUND(_xlpm.r/(_xlpm.u*(1-_xlpm.d)),0), "" ) ) ) -> 9 | H3: =_xlfn.LET( _xlpm.q,RawData!G3, _xlpm.u,RawData!H3, _xlpm.d,RawData!I3, _xlpm.r,RawData!J3, IF(AND(ISNUMBER(_xlpm.u),_xlpm.u>0),_xlpm.u, IF(AND(ISNUMBER(_xlpm.q),_xlpm.q>0,ISNUMBER(_xlpm.r),ISNUMBER(_xlpm.d),_xlpm.d>=0,_xlpm.d<1), _xlpm.r/(_xlpm.q*(1-_xlpm.d)), "" ) ) ) -> 48.13 | I3: =_xlfn.LET( _xlpm.q,RawData!G3, _xlpm.u,RawData!H3, _xlpm.d,RawData!I3, _xlpm.r,RawData!J3, IF(AND(ISNUMBER(_xlpm.d),_xlpm.d>=0,_xlpm.d<1),_xlpm.d, IF(AND(ISNUMBER(_xlpm.q),_xlpm.q>0,ISNUMBER(_xlpm.u),_xlpm.u>0,ISNUMBER(_xlpm.r),_xlpm.r>=0), 1-(_xlpm.r/(_xlpm.q*_xlpm.u)), "" ) ) ) -> 0 | J3: =_xlfn.LET( _xlpm.q,RawData!G3, _xlpm.u,RawData!H3, _xlpm.d,RawData!I3, _xlpm.r,RawData!J3, IF(AND(ISNUMBER(_xlpm.r),_xlpm.r>=0),_xlpm.r, IF(AND(ISNUMBER(_xlpm.q),_xlpm.q>0,ISNUMBER(_xlpm.u),_xlpm.u>0,ISNUMBER(_xlpm.d),_xlpm.d>=0,_xlpm.d<1), _xlpm.q*_xlpm.u*(1-_xlpm.d), "" ) ) ) -> 433.17 | K3: =_xlfn.LET( _xlpm.c,RawData!K3, _xlpm.r,RawData!J3, _xlpm.p,RawData!L3, IF(AND(ISNUMBER(_xlpm.c),_xlpm.c>=0),_xlpm.c, IF(AND(ISNUMBER(_xlpm.r),ISNUMBER(_xlpm.p)), _xlpm.r-_xlpm.p, "" ) ) ) -> 308.26 | L3: =_xlfn.LET( _xlpm.p,RawData!L3, _xlpm.r,RawData!J3, _xlpm.c,RawData!K3, IF(ISNUMBER(_xlpm.p),_xlpm.p, IF(AND(ISNUMBER(_xlpm.r),ISNUMBER(_xlpm.c)), _xlpm.r-_xlpm.c, "" ) )) -> 124.91
A4: ORD0003 | B4: 45874 | C4: =IF(RawData!C4="","Unknown",PROPER(TRIM(CLEAN(SUBSTITUTE(RawData!C4,CHAR(160)," "))))) -> North | D4: =IF(RawData!D4="","Unknown",PROPER(TRIM(CLEAN(SUBSTITUTE(RawData!D4,CHAR(160)," "))))) -> Delhi | E4: =IF(RawData!E4="","Unknown",PROPER(TRIM(CLEAN(SUBSTITUTE(RawData!E4,CHAR(160)," "))))) -> Laptop | F4: =IF(RawData!F4="","Unknown",PROPER(TRIM(CLEAN(SUBSTITUTE(RawData!F4,CHAR(160)," "))))) -> Electronics | G4: =_xlfn.LET( _xlpm.q,RawData!G4, _xlpm.u,RawData!H4, _xlpm.d,RawData!I4, _xlpm.r,RawData!J4, IF(AND(ISNUMBER(_xlpm.q),_xlpm.q>0),_xlpm.q, IF(AND(ISNUMBER(_xlpm.r),ISNUMBER(_xlpm.u),_xlpm.u>0,ISNUMBER(_xlpm.d),_xlpm.d>=0,_xlpm.d<1), ROUND(_xlpm.r/(_xlpm.u*(1-_xlpm.d)),0), "" ) ) ) -> 2 | H4: =_xlfn.LET( _xlpm.q,RawData!G4, _xlpm.u,RawData!H4, _xlpm.d,RawData!I4, _xlpm.r,RawData!J4, IF(AND(ISNUMBER(_xlpm.u),_xlpm.u>0),_xlpm.u, IF(AND(ISNUMBER(_xlpm.q),_xlpm.q>0,ISNUMBER(_xlpm.r),ISNUMBER(_xlpm.d),_xlpm.d>=0,_xlpm.d<1), _xlpm.r/(_xlpm.q*(1-_xlpm.d)), "" ) ) ) -> 762.28 | I4: =_xlfn.LET( _xlpm.q,RawData!G4, _xlpm.u,RawData!H4, _xlpm.d,RawData!I4, _xlpm.r,RawData!J4, IF(AND(ISNUMBER(_xlpm.d),_xlpm.d>=0,_xlpm.d<1),_xlpm.d, IF(AND(ISNUMBER(_xlpm.q),_xlpm.q>0,ISNUMBER(_xlpm.u),_xlpm.u>0,ISNUMBER(_xlpm.r),_xlpm.r>=0), 1-(_xlpm.r/(_xlpm.q*_xlpm.u)), "" ) ) ) -> 0.02 | J4: =_xlfn.LET( _xlpm.q,RawData!G4, _xlpm.u,RawData!H4, _xlpm.d,RawData!I4, _xlpm.r,RawData!J4, IF(AND(ISNUMBER(_xlpm.r),_xlpm.r>=0),_xlpm.r, IF(AND(ISNUMBER(_xlpm.q),_xlpm.q>0,ISNUMBER(_xlpm.u),_xlpm.u>0,ISNUMBER(_xlpm.d),_xlpm.d>=0,_xlpm.d<1), _xlpm.q*_xlpm.u*(1-_xlpm.d), "" ) ) ) -> 1494.07 | K4: =_xlfn.LET( _xlpm.c,RawData!K4, _xlpm.r,RawData!J4, _xlpm.p,RawData!L4, IF(AND(ISNUMBER(_xlpm.c),_xlpm.c>=0),_xlpm.c, IF(AND(ISNUMBER(_xlpm.r),ISNUMBER(_xlpm.p)), _xlpm.r-_xlpm.p, "" ) ) ) -> 884.67 | L4: =_xlfn.LET( _xlpm.p,RawData!L4, _xlpm.r,RawData!J4, _xlpm.c,RawData!K4, IF(ISNUMBER(_xlpm.p),_xlpm.p, IF(AND(ISNUMBER(_xlpm.r),ISNUMBER(_xlpm.c)), _xlpm.r-_xlpm.c, "" ) )) -> 609.4
A5: ORD0004 | B5: 45916 | C5: =IF(RawData!C5="","Unknown",PROPER(TRIM(CLEAN(SUBSTITUTE(RawData!C5,CHAR(160)," "))))) -> North | D5: =IF(RawData!D5="","Unknown",PROPER(TRIM(CLEAN(SUBSTITUTE(RawData!D5,CHAR(160)," "))))) -> Lucknow | E5: =IF(RawData!E5="","Unknown",PROPER(TRIM(CLEAN(SUBSTITUTE(RawData!E5,CHAR(160)," "))))) -> Notebook | F5: =IF(RawData!F5="","Unknown",PROPER(TRIM(CLEAN(SUBSTITUTE(RawData!F5,CHAR(160)," "))))) -> Office Supplies | G5: =_xlfn.LET( _xlpm.q,RawData!G5, _xlpm.u,RawData!H5, _xlpm.d,RawData!I5, _xlpm.r,RawData!J5, IF(AND(ISNUMBER(_xlpm.q),_xlpm.q>0),_xlpm.q, IF(AND(ISNUMBER(_xlpm.r),ISNUMBER(_xlpm.u),_xlpm.u>0,ISNUMBER(_xlpm.d),_xlpm.d>=0,_xlpm.d<1), ROUND(_xlpm.r/(_xlpm.u*(1-_xlpm.d)),0), "" ) ) ) -> 4 | H5: =_xlfn.LET( _xlpm.q,RawData!G5, _xlpm.u,RawData!H5, _xlpm.d,RawData!I5, _xlpm.r,RawData!J5, IF(AND(ISNUMBER(_xlpm.u),_xlpm.u>0),_xlpm.u, IF(AND(ISNUMBER(_xlpm.q),_xlpm.q>0,ISNUMBER(_xlpm.r),ISNUMBER(_xlpm.d),_xlpm.d>=0,_xlpm.d<1), _xlpm.r/(_xlpm.q*(1-_xlpm.d)), "" ) ) ) -> 6.94 | I5: =_xlfn.LET( _xlpm.q,RawData!G5, _xlpm.u,RawData!H5, _xlpm.d,RawData!I5, _xlpm.r,RawData!J5, IF(AND(ISNUMBER(_xlpm.d),_xlpm.d>=0,_xlpm.d<1),_xlpm.d, IF(AND(ISNUMBER(_xlpm.q),_xlpm.q>0,ISNUMBER(_xlpm.u),_xlpm.u>0,ISNUMBER(_xlpm.r),_xlpm.r>=0), 1-(_xlpm.r/(_xlpm.q*_xlpm.u)), "" ) ) ) -> 0.2 | J5: =_xlfn.LET( _xlpm.q,RawData!G5, _xlpm.u,RawData!H5, _xlpm.d,RawData!I5, _xlpm.r,RawData!J5, IF(AND(ISNUMBER(_xlpm.r),_xlpm.r>=0),_xlpm.r, IF(AND(ISNUMBER(_xlpm.q),_xlpm.q>0,ISNUMBER(_xlpm.u),_xlpm.u>0,ISNUMBER(_xlpm.d),_xlpm.d>=0,_xlpm.d<1), _xlpm.q*_xlpm.u*(1-_xlpm.d), "" ) ) ) -> 22.21 | K5: =_xlfn.LET( _xlpm.c,RawData!K5, _xlpm.r,RawData!J5, _xlpm.p,RawData!L5, IF(AND(ISNUMBER(_xlpm.c),_xlpm.c>=0),_xlpm.c, IF(AND(ISNUMBER(_xlpm.r),ISNUMBER(_xlpm.p)), _xlpm.r-_xlpm.p, "" ) ) ) -> 17.41 | L5: =_xlfn.LET( _xlpm.p,RawData!L5, _xlpm.r,RawData!J5, _xlpm.c,RawData!K5, IF(ISNUMBER(_xlpm.p),_xlpm.p, IF(AND(ISNUMBER(_xlpm.r),ISNUMBER(_xlpm.c)), _xlpm.r-_xlpm.c, "" ) )) -> 4.8
A6: ORD0005 | B6: 46017 | C6: =IF(RawData!C6="","Unknown",PROPER(TRIM(CLEAN(SUBSTITUTE(RawData!C6,CHAR(160)," "))))) -> West | D6: =IF(RawData!D6="","Unknown",PROPER(TRIM(CLEAN(SUBSTITUTE(RawData!D6,CHAR(160)," "))))) -> Pune | E6: =IF(RawData!E6="","Unknown",PROPER(TRIM(CLEAN(SUBSTITUTE(RawData!E6,CHAR(160)," "))))) -> Monitor | F6: =IF(RawData!F6="","Unknown",PROPER(TRIM(CLEAN(SUBSTITUTE(RawData!F6,CHAR(160)," "))))) -> Electronics | G6: =_xlfn.LET( _xlpm.q,RawData!G6, _xlpm.u,RawData!H6, _xlpm.d,RawData!I6, _xlpm.r,RawData!J6, IF(AND(ISNUMBER(_xlpm.q),_xlpm.q>0),_xlpm.q, IF(AND(ISNUMBER(_xlpm.r),ISNUMBER(_xlpm.u),_xlpm.u>0,ISNUMBER(_xlpm.d),_xlpm.d>=0,_xlpm.d<1), ROUND(_xlpm.r/(_xlpm.u*(1-_xlpm.d)),0), "" ) ) ) -> 8 | H6: =_xlfn.LET( _xlpm.q,RawData!G6, _xlpm.u,RawData!H6, _xlpm.d,RawData!I6, _xlpm.r,RawData!J6, IF(AND(ISNUMBER(_xlpm.u),_xlpm.u>0),_xlpm.u, IF(AND(ISNUMBER(_xlpm.q),_xlpm.q>0,ISNUMBER(_xlpm.r),ISNUMBER(_xlpm.d),_xlpm.d>=0,_xlpm.d<1), _xlpm.r/(_xlpm.q*(1-_xlpm.d)), "" ) ) ) -> 226.67 | I6: =_xlfn.LET( _xlpm.q,RawData!G6, _xlpm.u,RawData!H6, _xlpm.d,RawData!I6, _xlpm.r,RawData!J6, IF(AND(ISNUMBER(_xlpm.d),_xlpm.d>=0,_xlpm.d<1),_xlpm.d, IF(AND(ISNUMBER(_xlpm.q),_xlpm.q>0,ISNUMBER(_xlpm.u),_xlpm.u>0,ISNUMBER(_xlpm.r),_xlpm.r>=0), 1-(_xlpm.r/(_xlpm.q*_xlpm.u)), "" ) ) ) -> 0.15 | J6: =_xlfn.LET( _xlpm.q,RawData!G6, _xlpm.u,RawData!H6, _xlpm.d,RawData!I6, _xlpm.r,RawData!J6, IF(AND(ISNUMBER(_xlpm.r),_xlpm.r>=0),_xlpm.r, IF(AND(ISNUMBER(_xlpm.q),_xlpm.q>0,ISNUMBER(_xlpm.u),_xlpm.u>0,ISNUMBER(_xlpm.d),_xlpm.d>=0,_xlpm.d<1), _xlpm.q*_xlpm.u*(1-_xlpm.d), "" ) ) ) -> 1541.36 | K6: =_xlfn.LET( _xlpm.c,RawData!K6, _xlpm.r,RawData!J6, _xlpm.p,RawData!L6, IF(AND(ISNUMBER(_xlpm.c),_xlpm.c>=0),_xlpm.c, IF(AND(ISNUMBER(_xlpm.r),ISNUMBER(_xlpm.p)), _xlpm.r-_xlpm.p, "" ) ) ) -> 1142.42 | L6: =_xlfn.LET( _xlpm.p,RawData!L6, _xlpm.r,RawData!J6, _xlpm.c,RawData!K6, IF(ISNUMBER(_xlpm.p),_xlpm.p, IF(AND(ISNUMBER(_xlpm.r),ISNUMBER(_xlpm.c)), _xlpm.r-_xlpm.c, "" ) )) -> 398.94
A7: ORD0006 | B7: 45661 | C7: =IF(RawData!C7="","Unknown",PROPER(TRIM(CLEAN(SUBSTITUTE(RawData!C7,CHAR(160)," "))))) -> South | D7: =IF(RawData!D7="","Unknown",PROPER(TRIM(CLEAN(SUBSTITUTE(RawData!D7,CHAR(160)," "))))) -> Chennai | E7: =IF(RawData!E7="","Unknown",PROPER(TRIM(CLEAN(SUBSTITUTE(RawData!E7,CHAR(160)," "))))) -> Keyboard | F7: =IF(RawData!F7="","Unknown",PROPER(TRIM(CLEAN(SUBSTITUTE(RawData!F7,CHAR(160)," "))))) -> Accessories | G7: =_xlfn.LET( _xlpm.q,RawData!G7, _xlpm.u,RawData!H7, _xlpm.d,RawData!I7, _xlpm.r,RawData!J7, IF(AND(ISNUMBER(_xlpm.q),_xlpm.q>0),_xlpm.q, IF(AND(ISNUMBER(_xlpm.r),ISNUMBER(_xlpm.u),_xlpm.u>0,ISNUMBER(_xlpm.d),_xlpm.d>=0,_xlpm.d<1), ROUND(_xlpm.r/(_xlpm.u*(1-_xlpm.d)),0), "" ) ) ) -> 7 | H7: =_xlfn.LET( _xlpm.q,RawData!G7, _xlpm.u,RawData!H7, _xlpm.d,RawData!I7, _xlpm.r,RawData!J7, IF(AND(ISNUMBER(_xlpm.u),_xlpm.u>0),_xlpm.u, IF(AND(ISNUMBER(_xlpm.q),_xlpm.q>0,ISNUMBER(_xlpm.r),ISNUMBER(_xlpm.d),_xlpm.d>=0,_xlpm.d<1), _xlpm.r/(_xlpm.q*(1-_xlpm.d)), "" ) ) ) -> 29.97 | I7: =_xlfn.LET( _xlpm.q,RawData!G7, _xlpm.u,RawData!H7, _xlpm.d,RawData!I7, _xlpm.r,RawData!J7, IF(AND(ISNUMBER(_xlpm.d),_xlpm.d>=0,_xlpm.d<1),_xlpm.d, IF(AND(ISNUMBER(_xlpm.q),_xlpm.q>0,ISNUMBER(_xlpm.u),_xlpm.u>0,ISNUMBER(_xlpm.r),_xlpm.r>=0), 1-(_xlpm.r/(_xlpm.q*_xlpm.u)), "" ) ) ) -> 0.05 | J7: =_xlfn.LET( _xlpm.q,RawData!G7, _xlpm.u,RawData!H7, _xlpm.d,RawData!I7, _xlpm.r,RawData!J7, IF(AND(ISNUMBER(_xlpm.r),_xlpm.r>=0),_xlpm.r, IF(AND(ISNUMBER(_xlpm.q),_xlpm.q>0,ISNUMBER(_xlpm.u),_xlpm.u>0,ISNUMBER(_xlpm.d),_xlpm.d>=0,_xlpm.d<1), _xlpm.q*_xlpm.u*(1-_xlpm.d), "" ) ) ) -> 199.3 | K7: =_xlfn.LET( _xlpm.c,RawData!K7, _xlpm.r,RawData!J7, _xlpm.p,RawData!L7, IF(AND(ISNUMBER(_xlpm.c),_xlpm.c>=0),_xlpm.c, IF(AND(ISNUMBER(_xlpm.r),ISNUMBER(_xlpm.p)), _xlpm.r-_xlpm.p, "" ) ) ) -> 161.81 | L7: =_xlfn.LET( _xlpm.p,RawData!L7, _xlpm.r,RawData!J7, _xlpm.c,RawData!K7, IF(ISNUMBER(_xlpm.p),_xlpm.p, IF(AND(ISNUMBER(_xlpm.r),ISNUMBER(_xlpm.c)), _xlpm.r-_xlpm.c, "" ) )) -> 37.49
A8: ORD0007 | B8: 45737 | C8: =IF(RawData!C8="","Unknown",PROPER(TRIM(CLEAN(SUBSTITUTE(RawData!C8,CHAR(160)," "))))) -> South | D8: =IF(RawData!D8="","Unknown",PROPER(TRIM(CLEAN(SUBSTITUTE(RawData!D8,CHAR(160)," "))))) -> Chennai | E8: =IF(RawData!E8="","Unknown",PROPER(TRIM(CLEAN(SUBSTITUTE(RawData!E8,CHAR(160)," "))))) -> Desk | F8: =IF(RawData!F8="","Unknown",PROPER(TRIM(CLEAN(SUBSTITUTE(RawData!F8,CHAR(160)," "))))) -> Furniture | G8: =_xlfn.LET( _xlpm.q,RawData!G8, _xlpm.u,RawData!H8, _xlpm.d,RawData!I8, _xlpm.r,RawData!J8, IF(AND(ISNUMBER(_xlpm.q),_xlpm.q>0),_xlpm.q, IF(AND(ISNUMBER(_xlpm.r),ISNUMBER(_xlpm.u),_xlpm.u>0,ISNUMBER(_xlpm.d),_xlpm.d>=0,_xlpm.d<1), ROUND(_xlpm.r/(_xlpm.u*(1-_xlpm.d)),0), "" ) ) ) -> 2 | H8: =_xlfn.LET( _xlpm.q,RawData!G8, _xlpm.u,RawData!H8, _xlpm.d,RawData!I8, _xlpm.r,RawData!J8, IF(AND(ISNUMBER(_xlpm.u),_xlpm.u>0),_xlpm.u, IF(AND(ISNUMBER(_xlpm.q),_xlpm.q>0,ISNUMBER(_xlpm.r),ISNUMBER(_xlpm.d),_xlpm.d>=0,_xlpm.d<1), _xlpm.r/(_xlpm.q*(1-_xlpm.d)), "" ) ) ) -> 274.93 | I8: =_xlfn.LET( _xlpm.q,RawData!G8, _xlpm.u,RawData!H8, _xlpm.d,RawData!I8, _xlpm.r,RawData!J8, IF(AND(ISNUMBER(_xlpm.d),_xlpm.d>=0,_xlpm.d<1),_xlpm.d, IF(AND(ISNUMBER(_xlpm.q),_xlpm.q>0,ISNUMBER(_xlpm.u),_xlpm.u>0,ISNUMBER(_xlpm.r),_xlpm.r>=0), 1-(_xlpm.r/(_xlpm.q*_xlpm.u)), "" ) ) ) -> 0 | J8: =_xlfn.LET( _xlpm.q,RawData!G8, _xlpm.u,RawData!H8, _xlpm.d,RawData!I8, _xlpm.r,RawData!J8, IF(AND(ISNUMBER(_xlpm.r),_xlpm.r>=0),_xlpm.r, IF(AND(ISNUMBER(_xlpm.q),_xlpm.q>0,ISNUMBER(_xlpm.u),_xlpm.u>0,ISNUMBER(_xlpm.d),_xlpm.d>=0,_xlpm.d<1), _xlpm.q*_xlpm.u*(1-_xlpm.d), "" ) ) ) -> 549.86 | K8: =_xlfn.LET( _xlpm.c,RawData!K8, _xlpm.r,RawData!J8, _xlpm.p,RawData!L8, IF(AND(ISNUMBER(_xlpm.c),_xlpm.c>=0),_xlpm.c, IF(AND(ISNUMBER(_xlpm.r),ISNUMBER(_xlpm.p)), _xlpm.r-_xlpm.p, "" ) ) ) -> 333.95 | L8: =_xlfn.LET( _xlpm.p,RawData!L8, _xlpm.r,RawData!J8, _xlpm.c,RawData!K8, IF(ISNUMBER(_xlpm.p),_xlpm.p, IF(AND(ISNUMBER(_xlpm.r),ISNUMBER(_xlpm.c)), _xlpm.r-_xlpm.c, "" ) )) -> 215.91
A9: ORD0008 | B9: 45707 | C9: =IF(RawData!C9="","Unknown",PROPER(TRIM(CLEAN(SUBSTITUTE(RawData!C9,CHAR(160)," "))))) -> East | D9: =IF(RawData!D9="","Unknown",PROPER(TRIM(CLEAN(SUBSTITUTE(RawData!D9,CHAR(160)," "))))) -> Hyderabad | E9: =IF(RawData!E9="","Unknown",PROPER(TRIM(CLEAN(SUBSTITUTE(RawData!E9,CHAR(160)," "))))) -> Desk | F9: =IF(RawData!F9="","Unknown",PROPER(TRIM(CLEAN(SUBSTITUTE(RawData!F9,CHAR(160)," "))))) -> Furniture | G9: =_xlfn.LET( _xlpm.q,RawData!G9, _xlpm.u,RawData!H9, _xlpm.d,RawData!I9, _xlpm.r,RawData!J9, IF(AND(ISNUMBER(_xlpm.q),_xlpm.q>0),_xlpm.q, IF(AND(ISNUMBER(_xlpm.r),ISNUMBER(_xlpm.u),_xlpm.u>0,ISNUMBER(_xlpm.d),_xlpm.d>=0,_xlpm.d<1), ROUND(_xlpm.r/(_xlpm.u*(1-_xlpm.d)),0), "" ) ) ) -> 10 | H9: =_xlfn.LET( _xlpm.q,RawData!G9, _xlpm.u,RawData!H9, _xlpm.d,RawData!I9, _xlpm.r,RawData!J9, IF(AND(ISNUMBER(_xlpm.u),_xlpm.u>0),_xlpm.u, IF(AND(ISNUMBER(_xlpm.q),_xlpm.q>0,ISNUMBER(_xlpm.r),ISNUMBER(_xlpm.d),_xlpm.d>=0,_xlpm.d<1), _xlpm.r/(_xlpm.q*(1-_xlpm.d)), "" ) ) ) -> 226.14 | I9: =_xlfn.LET( _xlpm.q,RawData!G9, _xlpm.u,RawData!H9, _xlpm.d,RawData!I9, _xlpm.r,RawData!J9, IF(AND(ISNUMBER(_xlpm.d),_xlpm.d>=0,_xlpm.d<1),_xlpm.d, IF(AND(ISNUMBER(_xlpm.q),_xlpm.q>0,ISNUMBER(_xlpm.u),_xlpm.u>0,ISNUMBER(_xlpm.r),_xlpm.r>=0), 1-(_xlpm.r/(_xlpm.q*_xlpm.u)), "" ) ) ) -> 0.05 | J9: =_xlfn.LET( _xlpm.q,RawData!G9, _xlpm.u,RawData!H9, _xlpm.d,RawData!I9, _xlpm.r,RawData!J9, IF(AND(ISNUMBER(_xlpm.r),_xlpm.r>=0),_xlpm.r, IF(AND(ISNUMBER(_xlpm.q),_xlpm.q>0,ISNUMBER(_xlpm.u),_xlpm.u>0,ISNUMBER(_xlpm.d),_xlpm.d>=0,_xlpm.d<1), _xlpm.q*_xlpm.u*(1-_xlpm.d), "" ) ) ) -> 2148.33 | K9: =_xlfn.LET( _xlpm.c,RawData!K9, _xlpm.r,RawData!J9, _xlpm.p,RawData!L9, IF(AND(ISNUMBER(_xlpm.c),_xlpm.c>=0),_xlpm.c, IF(AND(ISNUMBER(_xlpm.r),ISNUMBER(_xlpm.p)), _xlpm.r-_xlpm.p, "" ) ) ) -> 1287.97 | L9: =_xlfn.LET( _xlpm.p,RawData!L9, _xlpm.r,RawData!J9, _xlpm.c,RawData!K9, IF(ISNUMBER(_xlpm.p),_xlpm.p, IF(AND(ISNUMBER(_xlpm.r),ISNUMBER(_xlpm.c)), _xlpm.r-_xlpm.c, "" ) )) -> 860.36
A10: ORD0009 | B10: 45893 | C10: =IF(RawData!C10="","Unknown",PROPER(TRIM(CLEAN(SUBSTITUTE(RawData!C10,CHAR(160)," "))))) -> North | D10: =IF(RawData!D10="","Unknown",PROPER(TRIM(CLEAN(SUBSTITUTE(RawData!D10,CHAR(160)," "))))) -> Jaipur | E10: =IF(RawData!E10="","Unknown",PROPER(TRIM(CLEAN(SUBSTITUTE(RawData!E10,CHAR(160)," "))))) -> Bookshelf | F10: =IF(RawData!F10="","Unknown",PROPER(TRIM(CLEAN(SUBSTITUTE(RawData!F10,CHAR(160)," "))))) -> Furniture | G10: =_xlfn.LET( _xlpm.q,RawData!G10, _xlpm.u,RawData!H10, _xlpm.d,RawData!I10, _xlpm.r,RawData!J10, IF(AND(ISNUMBER(_xlpm.q),_xlpm.q>0),_xlpm.q, IF(AND(ISNUMBER(_xlpm.r),ISNUMBER(_xlpm.u),_xlpm.u>0,ISNUMBER(_xlpm.d),_xlpm.d>=0,_xlpm.d<1), ROUND(_xlpm.r/(_xlpm.u*(1-_xlpm.d)),0), "" ) ) ) -> 2 | H10: =_xlfn.LET( _xlpm.q,RawData!G10, _xlpm.u,RawData!H10, _xlpm.d,RawData!I10, _xlpm.r,RawData!J10, IF(AND(ISNUMBER(_xlpm.u),_xlpm.u>0),_xlpm.u, IF(AND(ISNUMBER(_xlpm.q),_xlpm.q>0,ISNUMBER(_xlpm.r),ISNUMBER(_xlpm.d),_xlpm.d>=0,_xlpm.d<1), _xlpm.r/(_xlpm.q*(1-_xlpm.d)), "" ) ) ) -> 131.78 | I10: =_xlfn.LET( _xlpm.q,RawData!G10, _xlpm.u,RawData!H10, _xlpm.d,RawData!I10, _xlpm.r,RawData!J10, IF(AND(ISNUMBER(_xlpm.d),_xlpm.d>=0,_xlpm.d<1),_xlpm.d, IF(AND(ISNUMBER(_xlpm.q),_xlpm.q>0,ISNUMBER(_xlpm.u),_xlpm.u>0,ISNUMBER(_xlpm.r),_xlpm.r>=0), 1-(_xlpm.r/(_xlpm.q*_xlpm.u)), "" ) ) ) -> 0.15 | J10: =_xlfn.LET( _xlpm.q,RawData!G10, _xlpm.u,RawData!H10, _xlpm.d,RawData!I10, _xlpm.r,RawData!J10, IF(AND(ISNUMBER(_xlpm.r),_xlpm.r>=0),_xlpm.r, IF(AND(ISNUMBER(_xlpm.q),_xlpm.q>0,ISNUMBER(_xlpm.u),_xlpm.u>0,ISNUMBER(_xlpm.d),_xlpm.d>=0,_xlpm.d<1), _xlpm.q*_xlpm.u*(1-_xlpm.d), "" ) ) ) -> 224.03 | K10: =_xlfn.LET( _xlpm.c,RawData!K10, _xlpm.r,RawData!J10, _xlpm.p,RawData!L10, IF(AND(ISNUMBER(_xlpm.c),_xlpm.c>=0),_xlpm.c, IF(AND(ISNUMBER(_xlpm.r),ISNUMBER(_xlpm.p)), _xlpm.r-_xlpm.p, "" ) ) ) -> 154.96 | L10: =_xlfn.LET( _xlpm.p,RawData!L10, _xlpm.r,RawData!J10, _xlpm.c,RawData!K10, IF(ISNUMBER(_xlpm.p),_xlpm.p, IF(AND(ISNUMBER(_xlpm.r),ISNUMBER(_xlpm.c)), _xlpm.r-_xlpm.c, "" ) )) -> 69.07
A11: ORD0010 | B11: 45979 | C11: =IF(RawData!C11="","Unknown",PROPER(TRIM(CLEAN(SUBSTITUTE(RawData!C11,CHAR(160)," "))))) -> East | D11: =IF(RawData!D11="","Unknown",PROPER(TRIM(CLEAN(SUBSTITUTE(RawData!D11,CHAR(160)," "))))) -> Kolkata | E11: =IF(RawData!E11="","Unknown",PROPER(TRIM(CLEAN(SUBSTITUTE(RawData!E11,CHAR(160)," "))))) -> Pen Set | F11: =IF(RawData!F11="","Unknown",PROPER(TRIM(CLEAN(SUBSTITUTE(RawData!F11,CHAR(160)," "))))) -> Office Supplies | G11: =_xlfn.LET( _xlpm.q,RawData!G11, _xlpm.u,RawData!H11, _xlpm.d,RawData!I11, _xlpm.r,RawData!J11, IF(AND(ISNUMBER(_xlpm.q),_xlpm.q>0),_xlpm.q, IF(AND(ISNUMBER(_xlpm.r),ISNUMBER(_xlpm.u),_xlpm.u>0,ISNUMBER(_xlpm.d),_xlpm.d>=0,_xlpm.d<1), ROUND(_xlpm.r/(_xlpm.u*(1-_xlpm.d)),0), "" ) ) ) -> 4 | H11: =_xlfn.LET( _xlpm.q,RawData!G11, _xlpm.u,RawData!H11, _xlpm.d,RawData!I11, _xlpm.r,RawData!J11, IF(AND(ISNUMBER(_xlpm.u),_xlpm.u>0),_xlpm.u, IF(AND(ISNUMBER(_xlpm.q),_xlpm.q>0,ISNUMBER(_xlpm.r),ISNUMBER(_xlpm.d),_xlpm.d>=0,_xlpm.d<1), _xlpm.r/(_xlpm.q*(1-_xlpm.d)), "" ) ) ) -> 11.76 | I11: =_xlfn.LET( _xlpm.q,RawData!G11, _xlpm.u,RawData!H11, _xlpm.d,RawData!I11, _xlpm.r,RawData!J11, IF(AND(ISNUMBER(_xlpm.d),_xlpm.d>=0,_xlpm.d<1),_xlpm.d, IF(AND(ISNUMBER(_xlpm.q),_xlpm.q>0,ISNUMBER(_xlpm.u),_xlpm.u>0,ISNUMBER(_xlpm.r),_xlpm.r>=0), 1-(_xlpm.r/(_xlpm.q*_xlpm.u)), "" ) ) ) -> 0.2 | J11: =_xlfn.LET( _xlpm.q,RawData!G11, _xlpm.u,RawData!H11, _xlpm.d,RawData!I11, _xlpm.r,RawData!J11, IF(AND(ISNUMBER(_xlpm.r),_xlpm.r>=0),_xlpm.r, IF(AND(ISNUMBER(_xlpm.q),_xlpm.q>0,ISNUMBER(_xlpm.u),_xlpm.u>0,ISNUMBER(_xlpm.d),_xlpm.d>=0,_xlpm.d<1), _xlpm.q*_xlpm.u*(1-_xlpm.d), "" ) ) ) -> 37.63 | K11: =_xlfn.LET( _xlpm.c,RawData!K11, _xlpm.r,RawData!J11, _xlpm.p,RawData!L11, IF(AND(ISNUMBER(_xlpm.c),_xlpm.c>=0),_xlpm.c, IF(AND(ISNUMBER(_xlpm.r),ISNUMBER(_xlpm.p)), _xlpm.r-_xlpm.p, "" ) ) ) -> 23.66 | L11: =_xlfn.LET( _xlpm.p,RawData!L11, _xlpm.r,RawData!J11, _xlpm.c,RawData!K11, IF(ISNUMBER(_xlpm.p),_xlpm.p, IF(AND(ISNUMBER(_xlpm.r),ISNUMBER(_xlpm.c)), _xlpm.r-_xlpm.c, "" ) )) -> 13.97
A12: ORD0011 | B12: 45681 | C12: =IF(RawData!C12="","Unknown",PROPER(TRIM(CLEAN(SUBSTITUTE(RawData!C12,CHAR(160)," "))))) -> South | D12: =IF(RawData!D12="","Unknown",PROPER(TRIM(CLEAN(SUBSTITUTE(RawData!D12,CHAR(160)," "))))) -> Hyderabad | E12: =IF(RawData!E12="","Unknown",PROPER(TRIM(CLEAN(SUBSTITUTE(RawData!E12,CHAR(160)," "))))) -> Office Chair | F12: =IF(RawData!F12="","Unknown",PROPER(TRIM(CLEAN(SUBSTITUTE(RawData!F12,CHAR(160)," "))))) -> Furniture | G12: =_xlfn.LET( _xlpm.q,RawData!G12, _xlpm.u,RawData!H12, _xlpm.d,RawData!I12, _xlpm.r,RawData!J12, IF(AND(ISNUMBER(_xlpm.q),_xlpm.q>0),_xlpm.q, IF(AND(ISNUMBER(_xlpm.r),ISNUMBER(_xlpm.u),_xlpm.u>0,ISNUMBER(_xlpm.d),_xlpm.d>=0,_xlpm.d<1), ROUND(_xlpm.r/(_xlpm.u*(1-_xlpm.d)),0), "" ) ) ) -> 2 | H12: =_xlfn.LET( _xlpm.q,RawData!G12, _xlpm.u,RawData!H12, _xlpm.d,RawData!I12, _xlpm.r,RawData!J12, IF(AND(ISNUMBER(_xlpm.u),_xlpm.u>0),_xlpm.u, IF(AND(ISNUMBER(_xlpm.q),_xlpm.q>0,ISNUMBER(_xlpm.r),ISNUMBER(_xlpm.d),_xlpm.d>=0,_xlpm.d<1), _xlpm.r/(_xlpm.q*(1-_xlpm.d)), "" ) ) ) -> 186.04 | I12: =_xlfn.LET( _xlpm.q,RawData!G12, _xlpm.u,RawData!H12, _xlpm.d,RawData!I12, _xlpm.r,RawData!J12, IF(AND(ISNUMBER(_xlpm.d),_xlpm.d>=0,_xlpm.d<1),_xlpm.d, IF(AND(ISNUMBER(_xlpm.q),_xlpm.q>0,ISNUMBER(_xlpm.u),_xlpm.u>0,ISNUMBER(_xlpm.r),_xlpm.r>=0), 1-(_xlpm.r/(_xlpm.q*_xlpm.u)), "" ) ) ) -> 0.02 | J12: =_xlfn.LET( _xlpm.q,RawData!G12, _xlpm.u,RawData!H12, _xlpm.d,RawData!I12, _xlpm.r,RawData!J12, IF(AND(ISNUMBER(_xlpm.r),_xlpm.r>=0),_xlpm.r, IF(AND(ISNUMBER(_xlpm.q),_xlpm.q>0,ISNUMBER(_xlpm.u),_xlpm.u>0,ISNUMBER(_xlpm.d),_xlpm.d>=0,_xlpm.d<1), _xlpm.q*_xlpm.u*(1-_xlpm.d), "" ) ) ) -> 364.64 | K12: =_xlfn.LET( _xlpm.c,RawData!K12, _xlpm.r,RawData!J12, _xlpm.p,RawData!L12, IF(AND(ISNUMBER(_xlpm.c),_xlpm.c>=0),_xlpm.c, IF(AND(ISNUMBER(_xlpm.r),ISNUMBER(_xlpm.p)), _xlpm.r-_xlpm.p, "" ) ) ) -> 214.29 | L12: =_xlfn.LET( _xlpm.p,RawData!L12, _xlpm.r,RawData!J12, _xlpm.c,RawData!K12, IF(ISNUMBER(_xlpm.p),_xlpm.p, IF(AND(ISNUMBER(_xlpm.r),ISNUMBER(_xlpm.c)), _xlpm.r-_xlpm.c, "" ) )) -> 150.35
A13: ORD0012 | B13: 45852 | C13: =IF(RawData!C13="","Unknown",PROPER(TRIM(CLEAN(SUBSTITUTE(RawData!C13,CHAR(160)," "))))) -> East | D13: =IF(RawData!D13="","Unknown",PROPER(TRIM(CLEAN(SUBSTITUTE(RawData!D13,CHAR(160)," "))))) -> Bhubaneswar | E13: =IF(RawData!E13="","Unknown",PROPER(TRIM(CLEAN(SUBSTITUTE(RawData!E13,CHAR(160)," "))))) -> Printer | F13: =IF(RawData!F13="","Unknown",PROPER(TRIM(CLEAN(SUBSTITUTE(RawData!F13,CHAR(160)," "))))) -> Office Supplies | G13: =_xlfn.LET( _xlpm.q,RawData!G13, _xlpm.u,RawData!H13, _xlpm.d,RawData!I13, _xlpm.r,RawData!J13, IF(AND(ISNUMBER(_xlpm.q),_xlpm.q>0),_xlpm.q, IF(AND(ISNUMBER(_xlpm.r),ISNUMBER(_xlpm.u),_xlpm.u>0,ISNUMBER(_xlpm.d),_xlpm.d>=0,_xlpm.d<1), ROUND(_xlpm.r/(_xlpm.u*(1-_xlpm.d)),0), "" ) ) ) -> 6 | H13: =_xlfn.LET( _xlpm.q,RawData!G13, _xlpm.u,RawData!H13, _xlpm.d,RawData!I13, _xlpm.r,RawData!J13, IF(AND(ISNUMBER(_xlpm.u),_xlpm.u>0),_xlpm.u, IF(AND(ISNUMBER(_xlpm.q),_xlpm.q>0,ISNUMBER(_xlpm.r),ISNUMBER(_xlpm.d),_xlpm.d>=0,_xlpm.d<1), _xlpm.r/(_xlpm.q*(1-_xlpm.d)), "" ) ) ) -> 150.02 | I13: =_xlfn.LET( _xlpm.q,RawData!G13, _xlpm.u,RawData!H13, _xlpm.d,RawData!I13, _xlpm.r,RawData!J13, IF(AND(ISNUMBER(_xlpm.d),_xlpm.d>=0,_xlpm.d<1),_xlpm.d, IF(AND(ISNUMBER(_xlpm.q),_xlpm.q>0,ISNUMBER(_xlpm.u),_xlpm.u>0,ISNUMBER(_xlpm.r),_xlpm.r>=0), 1-(_xlpm.r/(_xlpm.q*_xlpm.u)), "" ) ) ) -> 0.02 | J13: =_xlfn.LET( _xlpm.q,RawData!G13, _xlpm.u,RawData!H13, _xlpm.d,RawData!I13, _xlpm.r,RawData!J13, IF(AND(ISNUMBER(_xlpm.r),_xlpm.r>=0),_xlpm.r, IF(AND(ISNUMBER(_xlpm.q),_xlpm.q>0,ISNUMBER(_xlpm.u),_xlpm.u>0,ISNUMBER(_xlpm.d),_xlpm.d>=0,_xlpm.d<1), _xlpm.q*_xlpm.u*(1-_xlpm.d), "" ) ) ) -> 882.12 | K13: =_xlfn.LET( _xlpm.c,RawData!K13, _xlpm.r,RawData!J13, _xlpm.p,RawData!L13, IF(AND(ISNUMBER(_xlpm.c),_xlpm.c>=0),_xlpm.c, IF(AND(ISNUMBER(_xlpm.r),ISNUMBER(_xlpm.p)), _xlpm.r-_xlpm.p, "" ) ) ) -> 572.42 | L13: =_xlfn.LET( _xlpm.p,RawData!L13, _xlpm.r,RawData!J13, _xlpm.c,RawData!K13, IF(ISNUMBER(_xlpm.p),_xlpm.p, IF(AND(ISNUMBER(_xlpm.r),ISNUMBER(_xlpm.c)), _xlpm.r-_xlpm.c, "" ) )) -> 309.7
... A535: ORD0534 | B535: 46018 | C535: =IF(RawData!C535="","Unknown",PROPER(TRIM(CLEAN(SUBSTITUTE(RawData!C535,CHAR(160)," "))))) -> South | D535: =IF(RawData!D535="","Unknown",PROPER(TRIM(CLEAN(SUBSTITUTE(RawData!D535,CHAR(160)," "))))) -> Hyderabad | E535: =IF(RawData!E535="","Unknown",PROPER(TRIM(CLEAN(SUBSTITUTE(RawData!E535,CHAR(160)," "))))) -> Monitor | F535: =IF(RawData!F535="","Unknown",PROPER(TRIM(CLEAN(SUBSTITUTE(RawData!F535,CHAR(160)," "))))) -> Electronics | G535: =_xlfn.LET( _xlpm.q,RawData!G535, _xlpm.u,RawData!H535, _xlpm.d,RawData!I535, _xlpm.r,RawData!J535, IF(AND(ISNUMBER(_xlpm.q),_xlpm.q>0),_xlpm.q, IF(AND(ISNUMBER(_xlpm.r),ISNUMBER(_xlpm.u),_xlpm.u>0,ISNUMBER(_xlpm.d),_xlpm.d>=0,_xlpm.d<1), ROUND(_xlpm.r/(_xlpm.u*(1-_xlpm.d)),0), "" ) ) ) -> 5 | H535: =_xlfn.LET( _xlpm.q,RawData!G535, _xlpm.u,RawData!H535, _xlpm.d,RawData!I535, _xlpm.r,RawData!J535, IF(AND(ISNUMBER(_xlpm.u),_xlpm.u>0),_xlpm.u, IF(AND(ISNUMBER(_xlpm.q),_xlpm.q>0,ISNUMBER(_xlpm.r),ISNUMBER(_xlpm.d),_xlpm.d>=0,_xlpm.d<1), _xlpm.r/(_xlpm.q*(1-_xlpm.d)), "" ) ) ) -> 202.76 | I535: =_xlfn.LET( _xlpm.q,RawData!G535, _xlpm.u,RawData!H535, _xlpm.d,RawData!I535, _xlpm.r,RawData!J535, IF(AND(ISNUMBER(_xlpm.d),_xlpm.d>=0,_xlpm.d<1),_xlpm.d, IF(AND(ISNUMBER(_xlpm.q),_xlpm.q>0,ISNUMBER(_xlpm.u),_xlpm.u>0,ISNUMBER(_xlpm.r),_xlpm.r>=0), 1-(_xlpm.r/(_xlpm.q*_xlpm.u)), "" ) ) ) -> 0.2 | J535: =_xlfn.LET( _xlpm.q,RawData!G535, _xlpm.u,RawData!H535, _xlpm.d,RawData!I535, _xlpm.r,RawData!J535, IF(AND(ISNUMBER(_xlpm.r),_xlpm.r>=0),_xlpm.r, IF(AND(ISNUMBER(_xlpm.q),_xlpm.q>0,ISNUMBER(_xlpm.u),_xlpm.u>0,ISNUMBER(_xlpm.d),_xlpm.d>=0,_xlpm.d<1), _xlpm.q*_xlpm.u*(1-_xlpm.d), "" ) ) ) -> 811.04 | K535: =_xlfn.LET( _xlpm.c,RawData!K535, _xlpm.r,RawData!J535, _xlpm.p,RawData!L535, IF(AND(ISNUMBER(_xlpm.c),_xlpm.c>=0),_xlpm.c, IF(AND(ISNUMBER(_xlpm.r),ISNUMBER(_xlpm.p)), _xlpm.r-_xlpm.p, "" ) ) ) -> 470.26 | L535: =_xlfn.LET( _xlpm.p,RawData!L535, _xlpm.r,RawData!J535, _xlpm.c,RawData!K535, IF(ISNUMBER(_xlpm.p),_xlpm.p, IF(AND(ISNUMBER(_xlpm.r),ISNUMBER(_xlpm.c)), _xlpm.r-_xlpm.c, "" ) )) -> 340.78
A536: ORD0535 | B536: 45953 | C536: =IF(RawData!C536="","Unknown",PROPER(TRIM(CLEAN(SUBSTITUTE(RawData!C536,CHAR(160)," "))))) -> North | D536: =IF(RawData!D536="","Unknown",PROPER(TRIM(CLEAN(SUBSTITUTE(RawData!D536,CHAR(160)," "))))) -> Jaipur | E536: =IF(RawData!E536="","Unknown",PROPER(TRIM(CLEAN(SUBSTITUTE(RawData!E536,CHAR(160)," "))))) -> Notebook | F536: =IF(RawData!F536="","Unknown",PROPER(TRIM(CLEAN(SUBSTITUTE(RawData!F536,CHAR(160)," "))))) -> Office Supplies | G536: =_xlfn.LET( _xlpm.q,RawData!G536, _xlpm.u,RawData!H536, _xlpm.d,RawData!I536, _xlpm.r,RawData!J536, IF(AND(ISNUMBER(_xlpm.q),_xlpm.q>0),_xlpm.q, IF(AND(ISNUMBER(_xlpm.r),ISNUMBER(_xlpm.u),_xlpm.u>0,ISNUMBER(_xlpm.d),_xlpm.d>=0,_xlpm.d<1), ROUND(_xlpm.r/(_xlpm.u*(1-_xlpm.d)),0), "" ) ) ) -> 3 | H536: =_xlfn.LET( _xlpm.q,RawData!G536, _xlpm.u,RawData!H536, _xlpm.d,RawData!I536, _xlpm.r,RawData!J536, IF(AND(ISNUMBER(_xlpm.u),_xlpm.u>0),_xlpm.u, IF(AND(ISNUMBER(_xlpm.q),_xlpm.q>0,ISNUMBER(_xlpm.r),ISNUMBER(_xlpm.d),_xlpm.d>=0,_xlpm.d<1), _xlpm.r/(_xlpm.q*(1-_xlpm.d)), "" ) ) ) -> 7.65 | I536: =_xlfn.LET( _xlpm.q,RawData!G536, _xlpm.u,RawData!H536, _xlpm.d,RawData!I536, _xlpm.r,RawData!J536, IF(AND(ISNUMBER(_xlpm.d),_xlpm.d>=0,_xlpm.d<1),_xlpm.d, IF(AND(ISNUMBER(_xlpm.q),_xlpm.q>0,ISNUMBER(_xlpm.u),_xlpm.u>0,ISNUMBER(_xlpm.r),_xlpm.r>=0), 1-(_xlpm.r/(_xlpm.q*_xlpm.u)), "" ) ) ) -> 0.05 | J536: =_xlfn.LET( _xlpm.q,RawData!G536, _xlpm.u,RawData!H536, _xlpm.d,RawData!I536, _xlpm.r,RawData!J536, IF(AND(ISNUMBER(_xlpm.r),_xlpm.r>=0),_xlpm.r, IF(AND(ISNUMBER(_xlpm.q),_xlpm.q>0,ISNUMBER(_xlpm.u),_xlpm.u>0,ISNUMBER(_xlpm.d),_xlpm.d>=0,_xlpm.d<1), _xlpm.q*_xlpm.u*(1-_xlpm.d), "" ) ) ) -> 21.8 | K536: =_xlfn.LET( _xlpm.c,RawData!K536, _xlpm.r,RawData!J536, _xlpm.p,RawData!L536, IF(AND(ISNUMBER(_xlpm.c),_xlpm.c>=0),_xlpm.c, IF(AND(ISNUMBER(_xlpm.r),ISNUMBER(_xlpm.p)), _xlpm.r-_xlpm.p, "" ) ) ) -> 13.68 | L536: =_xlfn.LET( _xlpm.p,RawData!L536, _xlpm.r,RawData!J536, _xlpm.c,RawData!K536, IF(ISNUMBER(_xlpm.p),_xlpm.p, IF(AND(ISNUMBER(_xlpm.r),ISNUMBER(_xlpm.c)), _xlpm.r-_xlpm.c, "" ) )) -> 8.12 | N536: =COUNTBLANK(H2:H601) -> 0
A537: ORD0536 | B537: 45758 | C537: =IF(RawData!C537="","Unknown",PROPER(TRIM(CLEAN(SUBSTITUTE(RawData!C537,CHAR(160)," "))))) -> West | D537: =IF(RawData!D537="","Unknown",PROPER(TRIM(CLEAN(SUBSTITUTE(RawData!D537,CHAR(160)," "))))) -> Pune | E537: =IF(RawData!E537="","Unknown",PROPER(TRIM(CLEAN(SUBSTITUTE(RawData!E537,CHAR(160)," "))))) -> Smartphone | F537: =IF(RawData!F537="","Unknown",PROPER(TRIM(CLEAN(SUBSTITUTE(RawData!F537,CHAR(160)," "))))) -> Electronics | G537: =_xlfn.LET( _xlpm.q,RawData!G537, _xlpm.u,RawData!H537, _xlpm.d,RawData!I537, _xlpm.r,RawData!J537, IF(AND(ISNUMBER(_xlpm.q),_xlpm.q>0),_xlpm.q, IF(AND(ISNUMBER(_xlpm.r),ISNUMBER(_xlpm.u),_xlpm.u>0,ISNUMBER(_xlpm.d),_xlpm.d>=0,_xlpm.d<1), ROUND(_xlpm.r/(_xlpm.u*(1-_xlpm.d)),0), "" ) ) ) -> 5 | H537: =_xlfn.LET( _xlpm.q,RawData!G537, _xlpm.u,RawData!H537, _xlpm.d,RawData!I537, _xlpm.r,RawData!J537, IF(AND(ISNUMBER(_xlpm.u),_xlpm.u>0),_xlpm.u, IF(AND(ISNUMBER(_xlpm.q),_xlpm.q>0,ISNUMBER(_xlpm.r),ISNUMBER(_xlpm.d),_xlpm.d>=0,_xlpm.d<1), _xlpm.r/(_xlpm.q*(1-_xlpm.d)), "" ) ) ) -> 516.39 | I537: =_xlfn.LET( _xlpm.q,RawData!G537, _xlpm.u,RawData!H537, _xlpm.d,RawData!I537, _xlpm.r,RawData!J537, IF(AND(ISNUMBER(_xlpm.d),_xlpm.d>=0,_xlpm.d<1),_xlpm.d, IF(AND(ISNUMBER(_xlpm.q),_xlpm.q>0,ISNUMBER(_xlpm.u),_xlpm.u>0,ISNUMBER(_xlpm.r),_xlpm.r>=0), 1-(_xlpm.r/(_xlpm.q*_xlpm.u)), "" ) ) ) -> 0.2 | J537: =_xlfn.LET( _xlpm.q,RawData!G537, _xlpm.u,RawData!H537, _xlpm.d,RawData!I537, _xlpm.r,RawData!J537, IF(AND(ISNUMBER(_xlpm.r),_xlpm.r>=0),_xlpm.r, IF(AND(ISNUMBER(_xlpm.q),_xlpm.q>0,ISNUMBER(_xlpm.u),_xlpm.u>0,ISNUMBER(_xlpm.d),_xlpm.d>=0,_xlpm.d<1), _xlpm.q*_xlpm.u*(1-_xlpm.d), "" ) ) ) -> 2065.56 | K537: =_xlfn.LET( _xlpm.c,RawData!K537, _xlpm.r,RawData!J537, _xlpm.p,RawData!L537, IF(AND(ISNUMBER(_xlpm.c),_xlpm.c>=0),_xlpm.c, IF(AND(ISNUMBER(_xlpm.r),ISNUMBER(_xlpm.p)), _xlpm.r-_xlpm.p, "" ) ) ) -> 1266.34 | L537: =_xlfn.LET( _xlpm.p,RawData!L537, _xlpm.r,RawData!J537, _xlpm.c,RawData!K537, IF(ISNUMBER(_xlpm.p),_xlpm.p, IF(AND(ISNUMBER(_xlpm.r),ISNUMBER(_xlpm.c)), _xlpm.r-_xlpm.c, "" ) )) -> 799.22
A538: ORD0537 | B538: 45928 | C538: =IF(RawData!C538="","Unknown",PROPER(TRIM(CLEAN(SUBSTITUTE(RawData!C538,CHAR(160)," "))))) -> East | D538: =IF(RawData!D538="","Unknown",PROPER(TRIM(CLEAN(SUBSTITUTE(RawData!D538,CHAR(160)," "))))) -> Bhubaneswar | E538: =IF(RawData!E538="","Unknown",PROPER(TRIM(CLEAN(SUBSTITUTE(RawData!E538,CHAR(160)," "))))) -> Pen Set | F538: =IF(RawData!F538="","Unknown",PROPER(TRIM(CLEAN(SUBSTITUTE(RawData!F538,CHAR(160)," "))))) -> Office Supplies | G538: =_xlfn.LET( _xlpm.q,RawData!G538, _xlpm.u,RawData!H538, _xlpm.d,RawData!I538, _xlpm.r,RawData!J538, IF(AND(ISNUMBER(_xlpm.q),_xlpm.q>0),_xlpm.q, IF(AND(ISNUMBER(_xlpm.r),ISNUMBER(_xlpm.u),_xlpm.u>0,ISNUMBER(_xlpm.d),_xlpm.d>=0,_xlpm.d<1), ROUND(_xlpm.r/(_xlpm.u*(1-_xlpm.d)),0), "" ) ) ) -> 7 | H538: =_xlfn.LET( _xlpm.q,RawData!G538, _xlpm.u,RawData!H538, _xlpm.d,RawData!I538, _xlpm.r,RawData!J538, IF(AND(ISNUMBER(_xlpm.u),_xlpm.u>0),_xlpm.u, IF(AND(ISNUMBER(_xlpm.q),_xlpm.q>0,ISNUMBER(_xlpm.r),ISNUMBER(_xlpm.d),_xlpm.d>=0,_xlpm.d<1), _xlpm.r/(_xlpm.q*(1-_xlpm.d)), "" ) ) ) -> 10.35 | I538: =_xlfn.LET( _xlpm.q,RawData!G538, _xlpm.u,RawData!H538, _xlpm.d,RawData!I538, _xlpm.r,RawData!J538, IF(AND(ISNUMBER(_xlpm.d),_xlpm.d>=0,_xlpm.d<1),_xlpm.d, IF(AND(ISNUMBER(_xlpm.q),_xlpm.q>0,ISNUMBER(_xlpm.u),_xlpm.u>0,ISNUMBER(_xlpm.r),_xlpm.r>=0), 1-(_xlpm.r/(_xlpm.q*_xlpm.u)), "" ) ) ) -> 0.15 | J538: =_xlfn.LET( _xlpm.q,RawData!G538, _xlpm.u,RawData!H538, _xlpm.d,RawData!I538, _xlpm.r,RawData!J538, IF(AND(ISNUMBER(_xlpm.r),_xlpm.r>=0),_xlpm.r, IF(AND(ISNUMBER(_xlpm.q),_xlpm.q>0,ISNUMBER(_xlpm.u),_xlpm.u>0,ISNUMBER(_xlpm.d),_xlpm.d>=0,_xlpm.d<1), _xlpm.q*_xlpm.u*(1-_xlpm.d), "" ) ) ) -> 61.58 | K538: =_xlfn.LET( _xlpm.c,RawData!K538, _xlpm.r,RawData!J538, _xlpm.p,RawData!L538, IF(AND(ISNUMBER(_xlpm.c),_xlpm.c>=0),_xlpm.c, IF(AND(ISNUMBER(_xlpm.r),ISNUMBER(_xlpm.p)), _xlpm.r-_xlpm.p, "" ) ) ) -> 34.17 | L538: =_xlfn.LET( _xlpm.p,RawData!L538, _xlpm.r,RawData!J538, _xlpm.c,RawData!K538, IF(ISNUMBER(_xlpm.p),_xlpm.p, IF(AND(ISNUMBER(_xlpm.r),ISNUMBER(_xlpm.c)), _xlpm.r-_xlpm.c, "" ) )) -> 27.41
A539: ORD0538 | B539: 45958 | C539: =IF(RawData!C539="","Unknown",PROPER(TRIM(CLEAN(SUBSTITUTE(RawData!C539,CHAR(160)," "))))) -> North | D539: =IF(RawData!D539="","Unknown",PROPER(TRIM(CLEAN(SUBSTITUTE(RawData!D539,CHAR(160)," "))))) -> Lucknow | E539: =IF(RawData!E539="","Unknown",PROPER(TRIM(CLEAN(SUBSTITUTE(RawData!E539,CHAR(160)," "))))) -> Desk | F539: =IF(RawData!F539="","Unknown",PROPER(TRIM(CLEAN(SUBSTITUTE(RawData!F539,CHAR(160)," "))))) -> Furniture | G539: =_xlfn.LET( _xlpm.q,RawData!G539, _xlpm.u,RawData!H539, _xlpm.d,RawData!I539, _xlpm.r,RawData!J539, IF(AND(ISNUMBER(_xlpm.q),_xlpm.q>0),_xlpm.q, IF(AND(ISNUMBER(_xlpm.r),ISNUMBER(_xlpm.u),_xlpm.u>0,ISNUMBER(_xlpm.d),_xlpm.d>=0,_xlpm.d<1), ROUND(_xlpm.r/(_xlpm.u*(1-_xlpm.d)),0), "" ) ) ) -> 6 | H539: =_xlfn.LET( _xlpm.q,RawData!G539, _xlpm.u,RawData!H539, _xlpm.d,RawData!I539, _xlpm.r,RawData!J539, IF(AND(ISNUMBER(_xlpm.u),_xlpm.u>0),_xlpm.u, IF(AND(ISNUMBER(_xlpm.q),_xlpm.q>0,ISNUMBER(_xlpm.r),ISNUMBER(_xlpm.d),_xlpm.d>=0,_xlpm.d<1), _xlpm.r/(_xlpm.q*(1-_xlpm.d)), "" ) ) ) -> 286.58 | I539: =_xlfn.LET( _xlpm.q,RawData!G539, _xlpm.u,RawData!H539, _xlpm.d,RawData!I539, _xlpm.r,RawData!J539, IF(AND(ISNUMBER(_xlpm.d),_xlpm.d>=0,_xlpm.d<1),_xlpm.d, IF(AND(ISNUMBER(_xlpm.q),_xlpm.q>0,ISNUMBER(_xlpm.u),_xlpm.u>0,ISNUMBER(_xlpm.r),_xlpm.r>=0), 1-(_xlpm.r/(_xlpm.q*_xlpm.u)), "" ) ) ) -> 0.1 | J539: =_xlfn.LET( _xlpm.q,RawData!G539, _xlpm.u,RawData!H539, _xlpm.d,RawData!I539, _xlpm.r,RawData!J539, IF(AND(ISNUMBER(_xlpm.r),_xlpm.r>=0),_xlpm.r, IF(AND(ISNUMBER(_xlpm.q),_xlpm.q>0,ISNUMBER(_xlpm.u),_xlpm.u>0,ISNUMBER(_xlpm.d),_xlpm.d>=0,_xlpm.d<1), _xlpm.q*_xlpm.u*(1-_xlpm.d), "" ) ) ) -> 1547.53 | K539: =_xlfn.LET( _xlpm.c,RawData!K539, _xlpm.r,RawData!J539, _xlpm.p,RawData!L539, IF(AND(ISNUMBER(_xlpm.c),_xlpm.c>=0),_xlpm.c, IF(AND(ISNUMBER(_xlpm.r),ISNUMBER(_xlpm.p)), _xlpm.r-_xlpm.p, "" ) ) ) -> 1029.88 | L539: =_xlfn.LET( _xlpm.p,RawData!L539, _xlpm.r,RawData!J539, _xlpm.c,RawData!K539, IF(ISNUMBER(_xlpm.p),_xlpm.p, IF(AND(ISNUMBER(_xlpm.r),ISNUMBER(_xlpm.c)), _xlpm.r-_xlpm.c, "" ) )) -> 517.65
A540: ORD0539 | B540: 45746 | C540: =IF(RawData!C540="","Unknown",PROPER(TRIM(CLEAN(SUBSTITUTE(RawData!C540,CHAR(160)," "))))) -> East | D540: =IF(RawData!D540="","Unknown",PROPER(TRIM(CLEAN(SUBSTITUTE(RawData!D540,CHAR(160)," "))))) -> Patna | E540: =IF(RawData!E540="","Unknown",PROPER(TRIM(CLEAN(SUBSTITUTE(RawData!E540,CHAR(160)," "))))) -> Pen Set | F540: =IF(RawData!F540="","Unknown",PROPER(TRIM(CLEAN(SUBSTITUTE(RawData!F540,CHAR(160)," "))))) -> Office Supplies | G540: =_xlfn.LET( _xlpm.q,RawData!G540, _xlpm.u,RawData!H540, _xlpm.d,RawData!I540, _xlpm.r,RawData!J540, IF(AND(ISNUMBER(_xlpm.q),_xlpm.q>0),_xlpm.q, IF(AND(ISNUMBER(_xlpm.r),ISNUMBER(_xlpm.u),_xlpm.u>0,ISNUMBER(_xlpm.d),_xlpm.d>=0,_xlpm.d<1), ROUND(_xlpm.r/(_xlpm.u*(1-_xlpm.d)),0), "" ) ) ) -> 10 | H540: =_xlfn.LET( _xlpm.q,RawData!G540, _xlpm.u,RawData!H540, _xlpm.d,RawData!I540, _xlpm.r,RawData!J540, IF(AND(ISNUMBER(_xlpm.u),_xlpm.u>0),_xlpm.u, IF(AND(ISNUMBER(_xlpm.q),_xlpm.q>0,ISNUMBER(_xlpm.r),ISNUMBER(_xlpm.d),_xlpm.d>=0,_xlpm.d<1), _xlpm.r/(_xlpm.q*(1-_xlpm.d)), "" ) ) ) -> 11.58 | I540: =_xlfn.LET( _xlpm.q,RawData!G540, _xlpm.u,RawData!H540, _xlpm.d,RawData!I540, _xlpm.r,RawData!J540, IF(AND(ISNUMBER(_xlpm.d),_xlpm.d>=0,_xlpm.d<1),_xlpm.d, IF(AND(ISNUMBER(_xlpm.q),_xlpm.q>0,ISNUMBER(_xlpm.u),_xlpm.u>0,ISNUMBER(_xlpm.r),_xlpm.r>=0), 1-(_xlpm.r/(_xlpm.q*_xlpm.u)), "" ) ) ) -> 0 | J540: =_xlfn.LET( _xlpm.q,RawData!G540, _xlpm.u,RawData!H540, _xlpm.d,RawData!I540, _xlpm.r,RawData!J540, IF(AND(ISNUMBER(_xlpm.r),_xlpm.r>=0),_xlpm.r, IF(AND(ISNUMBER(_xlpm.q),_xlpm.q>0,ISNUMBER(_xlpm.u),_xlpm.u>0,ISNUMBER(_xlpm.d),_xlpm.d>=0,_xlpm.d<1), _xlpm.q*_xlpm.u*(1-_xlpm.d), "" ) ) ) -> 115.8 | K540: =_xlfn.LET( _xlpm.c,RawData!K540, _xlpm.r,RawData!J540, _xlpm.p,RawData!L540, IF(AND(ISNUMBER(_xlpm.c),_xlpm.c>=0),_xlpm.c, IF(AND(ISNUMBER(_xlpm.r),ISNUMBER(_xlpm.p)), _xlpm.r-_xlpm.p, "" ) ) ) -> 84.94 | L540: =_xlfn.LET( _xlpm.p,RawData!L540, _xlpm.r,RawData!J540, _xlpm.c,RawData!K540, IF(ISNUMBER(_xlpm.p),_xlpm.p, IF(AND(ISNUMBER(_xlpm.r),ISNUMBER(_xlpm.c)), _xlpm.r-_xlpm.c, "" ) )) -> 30.86
A541: ORD0540 | B541: 45726 | C541: =IF(RawData!C541="","Unknown",PROPER(TRIM(CLEAN(SUBSTITUTE(RawData!C541,CHAR(160)," "))))) -> East | D541: =IF(RawData!D541="","Unknown",PROPER(TRIM(CLEAN(SUBSTITUTE(RawData!D541,CHAR(160)," "))))) -> Kolkata | E541: =IF(RawData!E541="","Unknown",PROPER(TRIM(CLEAN(SUBSTITUTE(RawData!E541,CHAR(160)," "))))) -> Smartphone | F541: =IF(RawData!F541="","Unknown",PROPER(TRIM(CLEAN(SUBSTITUTE(RawData!F541,CHAR(160)," "))))) -> Electronics | G541: =_xlfn.LET( _xlpm.q,RawData!G541, _xlpm.u,RawData!H541, _xlpm.d,RawData!I541, _xlpm.r,RawData!J541, IF(AND(ISNUMBER(_xlpm.q),_xlpm.q>0),_xlpm.q, IF(AND(ISNUMBER(_xlpm.r),ISNUMBER(_xlpm.u),_xlpm.u>0,ISNUMBER(_xlpm.d),_xlpm.d>=0,_xlpm.d<1), ROUND(_xlpm.r/(_xlpm.u*(1-_xlpm.d)),0), "" ) ) ) -> 4 | H541: =_xlfn.LET( _xlpm.q,RawData!G541, _xlpm.u,RawData!H541, _xlpm.d,RawData!I541, _xlpm.r,RawData!J541, IF(AND(ISNUMBER(_xlpm.u),_xlpm.u>0),_xlpm.u, IF(AND(ISNUMBER(_xlpm.q),_xlpm.q>0,ISNUMBER(_xlpm.r),ISNUMBER(_xlpm.d),_xlpm.d>=0,_xlpm.d<1), _xlpm.r/(_xlpm.q*(1-_xlpm.d)), "" ) ) ) -> 503.51 | I541: =_xlfn.LET( _xlpm.q,RawData!G541, _xlpm.u,RawData!H541, _xlpm.d,RawData!I541, _xlpm.r,RawData!J541, IF(AND(ISNUMBER(_xlpm.d),_xlpm.d>=0,_xlpm.d<1),_xlpm.d, IF(AND(ISNUMBER(_xlpm.q),_xlpm.q>0,ISNUMBER(_xlpm.u),_xlpm.u>0,ISNUMBER(_xlpm.r),_xlpm.r>=0), 1-(_xlpm.r/(_xlpm.q*_xlpm.u)), "" ) ) ) -> 0.05 | J541: =_xlfn.LET( _xlpm.q,RawData!G541, _xlpm.u,RawData!H541, _xlpm.d,RawData!I541, _xlpm.r,RawData!J541, IF(AND(ISNUMBER(_xlpm.r),_xlpm.r>=0),_xlpm.r, IF(AND(ISNUMBER(_xlpm.q),_xlpm.q>0,ISNUMBER(_xlpm.u),_xlpm.u>0,ISNUMBER(_xlpm.d),_xlpm.d>=0,_xlpm.d<1), _xlpm.q*_xlpm.u*(1-_xlpm.d), "" ) ) ) -> 1913.34 | K541: =_xlfn.LET( _xlpm.c,RawData!K541, _xlpm.r,RawData!J541, _xlpm.p,RawData!L541, IF(AND(ISNUMBER(_xlpm.c),_xlpm.c>=0),_xlpm.c, IF(AND(ISNUMBER(_xlpm.r),ISNUMBER(_xlpm.p)), _xlpm.r-_xlpm.p, "" ) ) ) -> 1543.09 | L541: =_xlfn.LET( _xlpm.p,RawData!L541, _xlpm.r,RawData!J541, _xlpm.c,RawData!K541, IF(ISNUMBER(_xlpm.p),_xlpm.p, IF(AND(ISNUMBER(_xlpm.r),ISNUMBER(_xlpm.c)), _xlpm.r-_xlpm.c, "" ) )) -> 370.25
A542: ORD0541 | B542: 45751 | C542: =IF(RawData!C542="","Unknown",PROPER(TRIM(CLEAN(SUBSTITUTE(RawData!C542,CHAR(160)," "))))) -> East | D542: =IF(RawData!D542="","Unknown",PROPER(TRIM(CLEAN(SUBSTITUTE(RawData!D542,CHAR(160)," "))))) -> Bhubaneswar | E542: =IF(RawData!E542="","Unknown",PROPER(TRIM(CLEAN(SUBSTITUTE(RawData!E542,CHAR(160)," "))))) -> Keyboard | F542: =IF(RawData!F542="","Unknown",PROPER(TRIM(CLEAN(SUBSTITUTE(RawData!F542,CHAR(160)," "))))) -> Accessories | G542: =_xlfn.LET( _xlpm.q,RawData!G542, _xlpm.u,RawData!H542, _xlpm.d,RawData!I542, _xlpm.r,RawData!J542, IF(AND(ISNUMBER(_xlpm.q),_xlpm.q>0),_xlpm.q, IF(AND(ISNUMBER(_xlpm.r),ISNUMBER(_xlpm.u),_xlpm.u>0,ISNUMBER(_xlpm.d),_xlpm.d>=0,_xlpm.d<1), ROUND(_xlpm.r/(_xlpm.u*(1-_xlpm.d)),0), "" ) ) ) -> 3 | H542: =_xlfn.LET( _xlpm.q,RawData!G542, _xlpm.u,RawData!H542, _xlpm.d,RawData!I542, _xlpm.r,RawData!J542, IF(AND(ISNUMBER(_xlpm.u),_xlpm.u>0),_xlpm.u, IF(AND(ISNUMBER(_xlpm.q),_xlpm.q>0,ISNUMBER(_xlpm.r),ISNUMBER(_xlpm.d),_xlpm.d>=0,_xlpm.d<1), _xlpm.r/(_xlpm.q*(1-_xlpm.d)), "" ) ) ) -> 38.01 | I542: =_xlfn.LET( _xlpm.q,RawData!G542, _xlpm.u,RawData!H542, _xlpm.d,RawData!I542, _xlpm.r,RawData!J542, IF(AND(ISNUMBER(_xlpm.d),_xlpm.d>=0,_xlpm.d<1),_xlpm.d, IF(AND(ISNUMBER(_xlpm.q),_xlpm.q>0,ISNUMBER(_xlpm.u),_xlpm.u>0,ISNUMBER(_xlpm.r),_xlpm.r>=0), 1-(_xlpm.r/(_xlpm.q*_xlpm.u)), "" ) ) ) -> 0.15 | J542: =_xlfn.LET( _xlpm.q,RawData!G542, _xlpm.u,RawData!H542, _xlpm.d,RawData!I542, _xlpm.r,RawData!J542, IF(AND(ISNUMBER(_xlpm.r),_xlpm.r>=0),_xlpm.r, IF(AND(ISNUMBER(_xlpm.q),_xlpm.q>0,ISNUMBER(_xlpm.u),_xlpm.u>0,ISNUMBER(_xlpm.d),_xlpm.d>=0,_xlpm.d<1), _xlpm.q*_xlpm.u*(1-_xlpm.d), "" ) ) ) -> 96.93 | K542: =_xlfn.LET( _xlpm.c,RawData!K542, _xlpm.r,RawData!J542, _xlpm.p,RawData!L542, IF(AND(ISNUMBER(_xlpm.c),_xlpm.c>=0),_xlpm.c, IF(AND(ISNUMBER(_xlpm.r),ISNUMBER(_xlpm.p)), _xlpm.r-_xlpm.p, "" ) ) ) -> 55.65 | L542: =_xlfn.LET( _xlpm.p,RawData!L542, _xlpm.r,RawData!J542, _xlpm.c,RawData!K542, IF(ISNUMBER(_xlpm.p),_xlpm.p, IF(AND(ISNUMBER(_xlpm.r),ISNUMBER(_xlpm.c)), _xlpm.r-_xlpm.c, "" ) )) -> 41.28
A543: ORD0542 | B543: 45872 | C543: =IF(RawData!C543="","Unknown",PROPER(TRIM(CLEAN(SUBSTITUTE(RawData!C543,CHAR(160)," "))))) -> South | D543: =IF(RawData!D543="","Unknown",PROPER(TRIM(CLEAN(SUBSTITUTE(RawData!D543,CHAR(160)," "))))) -> Hyderabad | E543: =IF(RawData!E543="","Unknown",PROPER(TRIM(CLEAN(SUBSTITUTE(RawData!E543,CHAR(160)," "))))) -> Pen Set | F543: =IF(RawData!F543="","Unknown",PROPER(TRIM(CLEAN(SUBSTITUTE(RawData!F543,CHAR(160)," "))))) -> Office Supplies | G543: =_xlfn.LET( _xlpm.q,RawData!G543, _xlpm.u,RawData!H543, _xlpm.d,RawData!I543, _xlpm.r,RawData!J543, IF(AND(ISNUMBER(_xlpm.q),_xlpm.q>0),_xlpm.q, IF(AND(ISNUMBER(_xlpm.r),ISNUMBER(_xlpm.u),_xlpm.u>0,ISNUMBER(_xlpm.d),_xlpm.d>=0,_xlpm.d<1), ROUND(_xlpm.r/(_xlpm.u*(1-_xlpm.d)),0), "" ) ) ) -> 7 | H543: =_xlfn.LET( _xlpm.q,RawData!G543, _xlpm.u,RawData!H543, _xlpm.d,RawData!I543, _xlpm.r,RawData!J543, IF(AND(ISNUMBER(_xlpm.u),_xlpm.u>0),_xlpm.u, IF(AND(ISNUMBER(_xlpm.q),_xlpm.q>0,ISNUMBER(_xlpm.r),ISNUMBER(_xlpm.d),_xlpm.d>=0,_xlpm.d<1), _xlpm.r/(_xlpm.q*(1-_xlpm.d)), "" ) ) ) -> 11.7 | I543: =_xlfn.LET( _xlpm.q,RawData!G543, _xlpm.u,RawData!H543, _xlpm.d,RawData!I543, _xlpm.r,RawData!J543, IF(AND(ISNUMBER(_xlpm.d),_xlpm.d>=0,_xlpm.d<1),_xlpm.d, IF(AND(ISNUMBER(_xlpm.q),_xlpm.q>0,ISNUMBER(_xlpm.u),_xlpm.u>0,ISNUMBER(_xlpm.r),_xlpm.r>=0), 1-(_xlpm.r/(_xlpm.q*_xlpm.u)), "" ) ) ) -> 0.1 | J543: =_xlfn.LET( _xlpm.q,RawData!G543, _xlpm.u,RawData!H543, _xlpm.d,RawData!I543, _xlpm.r,RawData!J543, IF(AND(ISNUMBER(_xlpm.r),_xlpm.r>=0),_xlpm.r, IF(AND(ISNUMBER(_xlpm.q),_xlpm.q>0,ISNUMBER(_xlpm.u),_xlpm.u>0,ISNUMBER(_xlpm.d),_xlpm.d>=0,_xlpm.d<1), _xlpm.q*_xlpm.u*(1-_xlpm.d), "" ) ) ) -> 73.71 | K543: =_xlfn.LET( _xlpm.c,RawData!K543, _xlpm.r,RawData!J543, _xlpm.p,RawData!L543, IF(AND(ISNUMBER(_xlpm.c),_xlpm.c>=0),_xlpm.c, IF(AND(ISNUMBER(_xlpm.r),ISNUMBER(_xlpm.p)), _xlpm.r-_xlpm.p, "" ) ) ) -> 58.04 | L543: =_xlfn.LET( _xlpm.p,RawData!L543, _xlpm.r,RawData!J543, _xlpm.c,RawData!K543, IF(ISNUMBER(_xlpm.p),_xlpm.p, IF(AND(ISNUMBER(_xlpm.r),ISNUMBER(_xlpm.c)), _xlpm.r-_xlpm.c, "" ) )) -> 15.67
A544: ORD0543 | B544: 45907 | C544: =IF(RawData!C544="","Unknown",PROPER(TRIM(CLEAN(SUBSTITUTE(RawData!C544,CHAR(160)," "))))) -> South | D544: =IF(RawData!D544="","Unknown",PROPER(TRIM(CLEAN(SUBSTITUTE(RawData!D544,CHAR(160)," "))))) -> Chennai | E544: =IF(RawData!E544="","Unknown",PROPER(TRIM(CLEAN(SUBSTITUTE(RawData!E544,CHAR(160)," "))))) -> Notebook | F544: =IF(RawData!F544="","Unknown",PROPER(TRIM(CLEAN(SUBSTITUTE(RawData!F544,CHAR(160)," "))))) -> Office Supplies | G544: =_xlfn.LET( _xlpm.q,RawData!G544, _xlpm.u,RawData!H544, _xlpm.d,RawData!I544, _xlpm.r,RawData!J544, IF(AND(ISNUMBER(_xlpm.q),_xlpm.q>0),_xlpm.q, IF(AND(ISNUMBER(_xlpm.r),ISNUMBER(_xlpm.u),_xlpm.u>0,ISNUMBER(_xlpm.d),_xlpm.d>=0,_xlpm.d<1), ROUND(_xlpm.r/(_xlpm.u*(1-_xlpm.d)),0), "" ) ) ) -> 3 | H544: =_xlfn.LET( _xlpm.q,RawData!G544, _xlpm.u,RawData!H544, _xlpm.d,RawData!I544, _xlpm.r,RawData!J544, IF(AND(ISNUMBER(_xlpm.u),_xlpm.u>0),_xlpm.u, IF(AND(ISNUMBER(_xlpm.q),_xlpm.q>0,ISNUMBER(_xlpm.r),ISNUMBER(_xlpm.d),_xlpm.d>=0,_xlpm.d<1), _xlpm.r/(_xlpm.q*(1-_xlpm.d)), "" ) ) ) -> 9.07 | I544: =_xlfn.LET( _xlpm.q,RawData!G544, _xlpm.u,RawData!H544, _xlpm.d,RawData!I544, _xlpm.r,RawData!J544, IF(AND(ISNUMBER(_xlpm.d),_xlpm.d>=0,_xlpm.d<1),_xlpm.d, IF(AND(ISNUMBER(_xlpm.q),_xlpm.q>0,ISNUMBER(_xlpm.u),_xlpm.u>0,ISNUMBER(_xlpm.r),_xlpm.r>=0), 1-(_xlpm.r/(_xlpm.q*_xlpm.u)), "" ) ) ) -> 0.1 | J544: =_xlfn.LET( _xlpm.q,RawData!G544, _xlpm.u,RawData!H544, _xlpm.d,RawData!I544, _xlpm.r,RawData!J544, IF(AND(ISNUMBER(_xlpm.r),_xlpm.r>=0),_xlpm.r, IF(AND(ISNUMBER(_xlpm.q),_xlpm.q>0,ISNUMBER(_xlpm.u),_xlpm.u>0,ISNUMBER(_xlpm.d),_xlpm.d>=0,_xlpm.d<1), _xlpm.q*_xlpm.u*(1-_xlpm.d), "" ) ) ) -> 24.49 | K544: =_xlfn.LET( _xlpm.c,RawData!K544, _xlpm.r,RawData!J544, _xlpm.p,RawData!L544, IF(AND(ISNUMBER(_xlpm.c),_xlpm.c>=0),_xlpm.c, IF(AND(ISNUMBER(_xlpm.r),ISNUMBER(_xlpm.p)), _xlpm.r-_xlpm.p, "" ) ) ) -> 16.56 | L544: =_xlfn.LET( _xlpm.p,RawData!L544, _xlpm.r,RawData!J544, _xlpm.c,RawData!K544, IF(ISNUMBER(_xlpm.p),_xlpm.p, IF(AND(ISNUMBER(_xlpm.r),ISNUMBER(_xlpm.c)), _xlpm.r-_xlpm.c, "" ) )) -> 7.93
A545: ORD0544 | B545: 45729 | C545: =IF(RawData!C545="","Unknown",PROPER(TRIM(CLEAN(SUBSTITUTE(RawData!C545,CHAR(160)," "))))) -> South | D545: =IF(RawData!D545="","Unknown",PROPER(TRIM(CLEAN(SUBSTITUTE(RawData!D545,CHAR(160)," "))))) -> Hyderabad | E545: =IF(RawData!E545="","Unknown",PROPER(TRIM(CLEAN(SUBSTITUTE(RawData!E545,CHAR(160)," "))))) -> Desk | F545: =IF(RawData!F545="","Unknown",PROPER(TRIM(CLEAN(SUBSTITUTE(RawData!F545,CHAR(160)," "))))) -> Furniture | G545: =_xlfn.LET( _xlpm.q,RawData!G545, _xlpm.u,RawData!H545, _xlpm.d,RawData!I545, _xlpm.r,RawData!J545, IF(AND(ISNUMBER(_xlpm.q),_xlpm.q>0),_xlpm.q, IF(AND(ISNUMBER(_xlpm.r),ISNUMBER(_xlpm.u),_xlpm.u>0,ISNUMBER(_xlpm.d),_xlpm.d>=0,_xlpm.d<1), ROUND(_xlpm.r/(_xlpm.u*(1-_xlpm.d)),0), "" ) ) ) -> 8 | H545: =_xlfn.LET( _xlpm.q,RawData!G545, _xlpm.u,RawData!H545, _xlpm.d,RawData!I545, _xlpm.r,RawData!J545, IF(AND(ISNUMBER(_xlpm.u),_xlpm.u>0),_xlpm.u, IF(AND(ISNUMBER(_xlpm.q),_xlpm.q>0,ISNUMBER(_xlpm.r),ISNUMBER(_xlpm.d),_xlpm.d>=0,_xlpm.d<1), _xlpm.r/(_xlpm.q*(1-_xlpm.d)), "" ) ) ) -> 258.51 | I545: =_xlfn.LET( _xlpm.q,RawData!G545, _xlpm.u,RawData!H545, _xlpm.d,RawData!I545, _xlpm.r,RawData!J545, IF(AND(ISNUMBER(_xlpm.d),_xlpm.d>=0,_xlpm.d<1),_xlpm.d, IF(AND(ISNUMBER(_xlpm.q),_xlpm.q>0,ISNUMBER(_xlpm.u),_xlpm.u>0,ISNUMBER(_xlpm.r),_xlpm.r>=0), 1-(_xlpm.r/(_xlpm.q*_xlpm.u)), "" ) ) ) -> 0.15 | J545: =_xlfn.LET( _xlpm.q,RawData!G545, _xlpm.u,RawData!H545, _xlpm.d,RawData!I545, _xlpm.r,RawData!J545, IF(AND(ISNUMBER(_xlpm.r),_xlpm.r>=0),_xlpm.r, IF(AND(ISNUMBER(_xlpm.q),_xlpm.q>0,ISNUMBER(_xlpm.u),_xlpm.u>0,ISNUMBER(_xlpm.d),_xlpm.d>=0,_xlpm.d<1), _xlpm.q*_xlpm.u*(1-_xlpm.d), "" ) ) ) -> 1757.87 | K545: =_xlfn.LET( _xlpm.c,RawData!K545, _xlpm.r,RawData!J545, _xlpm.p,RawData!L545, IF(AND(ISNUMBER(_xlpm.c),_xlpm.c>=0),_xlpm.c, IF(AND(ISNUMBER(_xlpm.r),ISNUMBER(_xlpm.p)), _xlpm.r-_xlpm.p, "" ) ) ) -> 1046.11 | L545: =_xlfn.LET( _xlpm.p,RawData!L545, _xlpm.r,RawData!J545, _xlpm.c,RawData!K545, IF(ISNUMBER(_xlpm.p),_xlpm.p, IF(AND(ISNUMBER(_xlpm.r),ISNUMBER(_xlpm.c)), _xlpm.r-_xlpm.c, "" ) )) -> 711.76
A546: ORD0545 | B546: 45841 | C546: =IF(RawData!C546="","Unknown",PROPER(TRIM(CLEAN(SUBSTITUTE(RawData!C546,CHAR(160)," "))))) -> North | D546: =IF(RawData!D546="","Unknown",PROPER(TRIM(CLEAN(SUBSTITUTE(RawData!D546,CHAR(160)," "))))) -> Jaipur | E546: =IF(RawData!E546="","Unknown",PROPER(TRIM(CLEAN(SUBSTITUTE(RawData!E546,CHAR(160)," "))))) -> Printer | F546: =IF(RawData!F546="","Unknown",PROPER(TRIM(CLEAN(SUBSTITUTE(RawData!F546,CHAR(160)," "))))) -> Office Supplies | G546: =_xlfn.LET( _xlpm.q,RawData!G546, _xlpm.u,RawData!H546, _xlpm.d,RawData!I546, _xlpm.r,RawData!J546, IF(AND(ISNUMBER(_xlpm.q),_xlpm.q>0),_xlpm.q, IF(AND(ISNUMBER(_xlpm.r),ISNUMBER(_xlpm.u),_xlpm.u>0,ISNUMBER(_xlpm.d),_xlpm.d>=0,_xlpm.d<1), ROUND(_xlpm.r/(_xlpm.u*(1-_xlpm.d)),0), "" ) ) ) -> 3 | H546: =_xlfn.LET( _xlpm.q,RawData!G546, _xlpm.u,RawData!H546, _xlpm.d,RawData!I546, _xlpm.r,RawData!J546, IF(AND(ISNUMBER(_xlpm.u),_xlpm.u>0),_xlpm.u, IF(AND(ISNUMBER(_xlpm.q),_xlpm.q>0,ISNUMBER(_xlpm.r),ISNUMBER(_xlpm.d),_xlpm.d>=0,_xlpm.d<1), _xlpm.r/(_xlpm.q*(1-_xlpm.d)), "" ) ) ) -> 183.58 | I546: =_xlfn.LET( _xlpm.q,RawData!G546, _xlpm.u,RawData!H546, _xlpm.d,RawData!I546, _xlpm.r,RawData!J546, IF(AND(ISNUMBER(_xlpm.d),_xlpm.d>=0,_xlpm.d<1),_xlpm.d, IF(AND(ISNUMBER(_xlpm.q),_xlpm.q>0,ISNUMBER(_xlpm.u),_xlpm.u>0,ISNUMBER(_xlpm.r),_xlpm.r>=0), 1-(_xlpm.r/(_xlpm.q*_xlpm.u)), "" ) ) ) -> 0.02 | J546: =_xlfn.LET( _xlpm.q,RawData!G546, _xlpm.u,RawData!H546, _xlpm.d,RawData!I546, _xlpm.r,RawData!J546, IF(AND(ISNUMBER(_xlpm.r),_xlpm.r>=0),_xlpm.r, IF(AND(ISNUMBER(_xlpm.q),_xlpm.q>0,ISNUMBER(_xlpm.u),_xlpm.u>0,ISNUMBER(_xlpm.d),_xlpm.d>=0,_xlpm.d<1), _xlpm.q*_xlpm.u*(1-_xlpm.d), "" ) ) ) -> 539.73 | K546: =_xlfn.LET( _xlpm.c,RawData!K546, _xlpm.r,RawData!J546, _xlpm.p,RawData!L546, IF(AND(ISNUMBER(_xlpm.c),_xlpm.c>=0),_xlpm.c, IF(AND(ISNUMBER(_xlpm.r),ISNUMBER(_xlpm.p)), _xlpm.r-_xlpm.p, "" ) ) ) -> 330.61 | L546: =_xlfn.LET( _xlpm.p,RawData!L546, _xlpm.r,RawData!J546, _xlpm.c,RawData!K546, IF(ISNUMBER(_xlpm.p),_xlpm.p, IF(AND(ISNUMBER(_xlpm.r),ISNUMBER(_xlpm.c)), _xlpm.r-_xlpm.c, "" ) )) -> 209.12
A547: ORD0546 | B547: 45945 | C547: =IF(RawData!C547="","Unknown",PROPER(TRIM(CLEAN(SUBSTITUTE(RawData!C547,CHAR(160)," "))))) -> West | D547: =IF(RawData!D547="","Unknown",PROPER(TRIM(CLEAN(SUBSTITUTE(RawData!D547,CHAR(160)," "))))) -> Ahmedabad | E547: =IF(RawData!E547="","Unknown",PROPER(TRIM(CLEAN(SUBSTITUTE(RawData!E547,CHAR(160)," "))))) -> Bookshelf | F547: =IF(RawData!F547="","Unknown",PROPER(TRIM(CLEAN(SUBSTITUTE(RawData!F547,CHAR(160)," "))))) -> Furniture | G547: =_xlfn.LET( _xlpm.q,RawData!G547, _xlpm.u,RawData!H547, _xlpm.d,RawData!I547, _xlpm.r,RawData!J547, IF(AND(ISNUMBER(_xlpm.q),_xlpm.q>0),_xlpm.q, IF(AND(ISNUMBER(_xlpm.r),ISNUMBER(_xlpm.u),_xlpm.u>0,ISNUMBER(_xlpm.d),_xlpm.d>=0,_xlpm.d<1), ROUND(_xlpm.r/(_xlpm.u*(1-_xlpm.d)),0), "" ) ) ) -> 8 | H547: =_xlfn.LET( _xlpm.q,RawData!G547, _xlpm.u,RawData!H547, _xlpm.d,RawData!I547, _xlpm.r,RawData!J547, IF(AND(ISNUMBER(_xlpm.u),_xlpm.u>0),_xlpm.u, IF(AND(ISNUMBER(_xlpm.q),_xlpm.q>0,ISNUMBER(_xlpm.r),ISNUMBER(_xlpm.d),_xlpm.d>=0,_xlpm.d<1), _xlpm.r/(_xlpm.q*(1-_xlpm.d)), "" ) ) ) -> 158.59 | I547: =_xlfn.LET( _xlpm.q,RawData!G547, _xlpm.u,RawData!H547, _xlpm.d,RawData!I547, _xlpm.r,RawData!J547, IF(AND(ISNUMBER(_xlpm.d),_xlpm.d>=0,_xlpm.d<1),_xlpm.d, IF(AND(ISNUMBER(_xlpm.q),_xlpm.q>0,ISNUMBER(_xlpm.u),_xlpm.u>0,ISNUMBER(_xlpm.r),_xlpm.r>=0), 1-(_xlpm.r/(_xlpm.q*_xlpm.u)), "" ) ) ) -> 0.1 | J547: =_xlfn.LET( _xlpm.q,RawData!G547, _xlpm.u,RawData!H547, _xlpm.d,RawData!I547, _xlpm.r,RawData!J547, IF(AND(ISNUMBER(_xlpm.r),_xlpm.r>=0),_xlpm.r, IF(AND(ISNUMBER(_xlpm.q),_xlpm.q>0,ISNUMBER(_xlpm.u),_xlpm.u>0,ISNUMBER(_xlpm.d),_xlpm.d>=0,_xlpm.d<1), _xlpm.q*_xlpm.u*(1-_xlpm.d), "" ) ) ) -> 1141.85 | K547: =_xlfn.LET( _xlpm.c,RawData!K547, _xlpm.r,RawData!J547, _xlpm.p,RawData!L547, IF(AND(ISNUMBER(_xlpm.c),_xlpm.c>=0),_xlpm.c, IF(AND(ISNUMBER(_xlpm.r),ISNUMBER(_xlpm.p)), _xlpm.r-_xlpm.p, "" ) ) ) -> 828.3 | L547: =_xlfn.LET( _xlpm.p,RawData!L547, _xlpm.r,RawData!J547, _xlpm.c,RawData!K547, IF(ISNUMBER(_xlpm.p),_xlpm.p, IF(AND(ISNUMBER(_xlpm.r),ISNUMBER(_xlpm.c)), _xlpm.r-_xlpm.c, "" ) )) -> 313.55
